{
 "cells": [
  {
   "cell_type": "code",
   "execution_count": 2,
   "metadata": {},
   "outputs": [
    {
     "name": "stdout",
     "output_type": "stream",
     "text": [
      "Defaulting to user installation because normal site-packages is not writeable\n",
      "Requirement already satisfied: gradio in c:\\users\\shjung\\appdata\\roaming\\python\\python38\\site-packages (4.10.0)\n",
      "Requirement already satisfied: aiofiles<24.0,>=22.0 in c:\\users\\shjung\\appdata\\roaming\\python\\python38\\site-packages (from gradio) (23.2.1)\n",
      "Requirement already satisfied: altair<6.0,>=4.2.0 in c:\\users\\shjung\\appdata\\roaming\\python\\python38\\site-packages (from gradio) (5.4.1)\n",
      "Requirement already satisfied: fastapi in c:\\users\\shjung\\appdata\\roaming\\python\\python38\\site-packages (from gradio) (0.115.0)\n",
      "Requirement already satisfied: ffmpy in c:\\users\\shjung\\appdata\\roaming\\python\\python38\\site-packages (from gradio) (0.4.0)\n",
      "Requirement already satisfied: gradio-client==0.7.3 in c:\\users\\shjung\\appdata\\roaming\\python\\python38\\site-packages (from gradio) (0.7.3)\n",
      "Requirement already satisfied: httpx in c:\\anaconda3\\envs\\cv2\\lib\\site-packages (from gradio) (0.27.2)\n",
      "Requirement already satisfied: huggingface-hub>=0.19.3 in c:\\users\\shjung\\appdata\\roaming\\python\\python38\\site-packages (from gradio) (0.25.1)\n",
      "Requirement already satisfied: importlib-resources<7.0,>=1.3 in c:\\anaconda3\\envs\\cv2\\lib\\site-packages (from gradio) (6.4.2)\n",
      "Requirement already satisfied: jinja2<4.0 in c:\\users\\shjung\\appdata\\roaming\\python\\python38\\site-packages (from gradio) (3.1.4)\n",
      "Requirement already satisfied: markupsafe~=2.0 in c:\\users\\shjung\\appdata\\roaming\\python\\python38\\site-packages (from gradio) (2.1.5)\n",
      "Requirement already satisfied: matplotlib~=3.0 in c:\\anaconda3\\envs\\cv2\\lib\\site-packages (from gradio) (3.7.5)\n",
      "Requirement already satisfied: numpy~=1.0 in c:\\anaconda3\\envs\\cv2\\lib\\site-packages (from gradio) (1.24.4)\n",
      "Requirement already satisfied: orjson~=3.0 in c:\\users\\shjung\\appdata\\roaming\\python\\python38\\site-packages (from gradio) (3.10.7)\n",
      "Requirement already satisfied: packaging in c:\\anaconda3\\envs\\cv2\\lib\\site-packages (from gradio) (24.1)\n",
      "Requirement already satisfied: pandas<3.0,>=1.0 in c:\\users\\shjung\\appdata\\roaming\\python\\python38\\site-packages (from gradio) (2.0.3)\n",
      "Requirement already satisfied: pillow<11.0,>=8.0 in c:\\anaconda3\\envs\\cv2\\lib\\site-packages (from gradio) (10.4.0)\n",
      "Requirement already satisfied: pydantic>=2.0 in c:\\anaconda3\\envs\\cv2\\lib\\site-packages (from gradio) (2.9.2)\n",
      "Requirement already satisfied: pydub in c:\\users\\shjung\\appdata\\roaming\\python\\python38\\site-packages (from gradio) (0.25.1)\n",
      "Requirement already satisfied: python-multipart in c:\\users\\shjung\\appdata\\roaming\\python\\python38\\site-packages (from gradio) (0.0.10)\n",
      "Requirement already satisfied: pyyaml<7.0,>=5.0 in c:\\anaconda3\\envs\\cv2\\lib\\site-packages (from gradio) (6.0.2)\n",
      "Requirement already satisfied: semantic-version~=2.0 in c:\\users\\shjung\\appdata\\roaming\\python\\python38\\site-packages (from gradio) (2.10.0)\n",
      "Requirement already satisfied: tomlkit==0.12.0 in c:\\users\\shjung\\appdata\\roaming\\python\\python38\\site-packages (from gradio) (0.12.0)\n",
      "Requirement already satisfied: typer<1.0,>=0.9 in c:\\users\\shjung\\appdata\\roaming\\python\\python38\\site-packages (from typer[all]<1.0,>=0.9->gradio) (0.12.5)\n",
      "Requirement already satisfied: typing-extensions~=4.0 in c:\\users\\shjung\\appdata\\roaming\\python\\python38\\site-packages (from gradio) (4.12.2)\n",
      "Requirement already satisfied: uvicorn>=0.14.0 in c:\\users\\shjung\\appdata\\roaming\\python\\python38\\site-packages (from gradio) (0.30.6)\n",
      "Requirement already satisfied: fsspec in c:\\users\\shjung\\appdata\\roaming\\python\\python38\\site-packages (from gradio-client==0.7.3->gradio) (2024.9.0)\n",
      "Requirement already satisfied: websockets<12.0,>=10.0 in c:\\users\\shjung\\appdata\\roaming\\python\\python38\\site-packages (from gradio-client==0.7.3->gradio) (11.0.3)\n",
      "Requirement already satisfied: jsonschema>=3.0 in c:\\users\\shjung\\appdata\\roaming\\python\\python38\\site-packages (from altair<6.0,>=4.2.0->gradio) (4.23.0)\n",
      "Requirement already satisfied: narwhals>=1.5.2 in c:\\users\\shjung\\appdata\\roaming\\python\\python38\\site-packages (from altair<6.0,>=4.2.0->gradio) (1.8.3)\n",
      "Requirement already satisfied: filelock in c:\\users\\shjung\\appdata\\roaming\\python\\python38\\site-packages (from huggingface-hub>=0.19.3->gradio) (3.16.1)\n",
      "Requirement already satisfied: requests in c:\\anaconda3\\envs\\cv2\\lib\\site-packages (from huggingface-hub>=0.19.3->gradio) (2.32.3)\n",
      "Requirement already satisfied: tqdm>=4.42.1 in c:\\anaconda3\\envs\\cv2\\lib\\site-packages (from huggingface-hub>=0.19.3->gradio) (4.66.5)\n",
      "Requirement already satisfied: zipp>=3.1.0 in c:\\anaconda3\\envs\\cv2\\lib\\site-packages (from importlib-resources<7.0,>=1.3->gradio) (3.17.0)\n",
      "Requirement already satisfied: contourpy>=1.0.1 in c:\\anaconda3\\envs\\cv2\\lib\\site-packages (from matplotlib~=3.0->gradio) (1.1.1)\n",
      "Requirement already satisfied: cycler>=0.10 in c:\\anaconda3\\envs\\cv2\\lib\\site-packages (from matplotlib~=3.0->gradio) (0.12.1)\n",
      "Requirement already satisfied: fonttools>=4.22.0 in c:\\anaconda3\\envs\\cv2\\lib\\site-packages (from matplotlib~=3.0->gradio) (4.53.1)\n",
      "Requirement already satisfied: kiwisolver>=1.0.1 in c:\\anaconda3\\envs\\cv2\\lib\\site-packages (from matplotlib~=3.0->gradio) (1.4.5)\n",
      "Requirement already satisfied: pyparsing>=2.3.1 in c:\\anaconda3\\envs\\cv2\\lib\\site-packages (from matplotlib~=3.0->gradio) (3.1.2)\n",
      "Requirement already satisfied: python-dateutil>=2.7 in c:\\anaconda3\\envs\\cv2\\lib\\site-packages (from matplotlib~=3.0->gradio) (2.9.0.post0)\n",
      "Requirement already satisfied: pytz>=2020.1 in c:\\users\\shjung\\appdata\\roaming\\python\\python38\\site-packages (from pandas<3.0,>=1.0->gradio) (2024.2)\n",
      "Requirement already satisfied: tzdata>=2022.1 in c:\\users\\shjung\\appdata\\roaming\\python\\python38\\site-packages (from pandas<3.0,>=1.0->gradio) (2024.2)\n",
      "Requirement already satisfied: annotated-types>=0.6.0 in c:\\anaconda3\\envs\\cv2\\lib\\site-packages (from pydantic>=2.0->gradio) (0.7.0)\n",
      "Requirement already satisfied: pydantic-core==2.23.4 in c:\\anaconda3\\envs\\cv2\\lib\\site-packages (from pydantic>=2.0->gradio) (2.23.4)\n",
      "Requirement already satisfied: click>=8.0.0 in c:\\users\\shjung\\appdata\\roaming\\python\\python38\\site-packages (from typer<1.0,>=0.9->typer[all]<1.0,>=0.9->gradio) (8.1.7)\n",
      "Requirement already satisfied: shellingham>=1.3.0 in c:\\users\\shjung\\appdata\\roaming\\python\\python38\\site-packages (from typer<1.0,>=0.9->typer[all]<1.0,>=0.9->gradio) (1.5.4)\n",
      "Requirement already satisfied: rich>=10.11.0 in c:\\users\\shjung\\appdata\\roaming\\python\\python38\\site-packages (from typer<1.0,>=0.9->typer[all]<1.0,>=0.9->gradio) (13.8.1)\n",
      "Requirement already satisfied: h11>=0.8 in c:\\anaconda3\\envs\\cv2\\lib\\site-packages (from uvicorn>=0.14.0->gradio) (0.14.0)\n",
      "Requirement already satisfied: starlette<0.39.0,>=0.37.2 in c:\\users\\shjung\\appdata\\roaming\\python\\python38\\site-packages (from fastapi->gradio) (0.38.6)\n",
      "Requirement already satisfied: anyio in c:\\anaconda3\\envs\\cv2\\lib\\site-packages (from httpx->gradio) (4.5.0)\n",
      "Requirement already satisfied: certifi in c:\\anaconda3\\envs\\cv2\\lib\\site-packages (from httpx->gradio) (2024.8.30)\n",
      "Requirement already satisfied: httpcore==1.* in c:\\anaconda3\\envs\\cv2\\lib\\site-packages (from httpx->gradio) (1.0.5)\n",
      "Requirement already satisfied: idna in c:\\anaconda3\\envs\\cv2\\lib\\site-packages (from httpx->gradio) (3.8)\n",
      "Requirement already satisfied: sniffio in c:\\anaconda3\\envs\\cv2\\lib\\site-packages (from httpx->gradio) (1.3.1)\n",
      "Requirement already satisfied: colorama in c:\\anaconda3\\envs\\cv2\\lib\\site-packages (from click>=8.0.0->typer<1.0,>=0.9->typer[all]<1.0,>=0.9->gradio) (0.4.6)\n",
      "Requirement already satisfied: attrs>=22.2.0 in c:\\anaconda3\\envs\\cv2\\lib\\site-packages (from jsonschema>=3.0->altair<6.0,>=4.2.0->gradio) (24.2.0)\n",
      "Requirement already satisfied: jsonschema-specifications>=2023.03.6 in c:\\users\\shjung\\appdata\\roaming\\python\\python38\\site-packages (from jsonschema>=3.0->altair<6.0,>=4.2.0->gradio) (2023.12.1)\n",
      "Requirement already satisfied: pkgutil-resolve-name>=1.3.10 in c:\\users\\shjung\\appdata\\roaming\\python\\python38\\site-packages (from jsonschema>=3.0->altair<6.0,>=4.2.0->gradio) (1.3.10)\n",
      "Requirement already satisfied: referencing>=0.28.4 in c:\\users\\shjung\\appdata\\roaming\\python\\python38\\site-packages (from jsonschema>=3.0->altair<6.0,>=4.2.0->gradio) (0.35.1)\n",
      "Requirement already satisfied: rpds-py>=0.7.1 in c:\\users\\shjung\\appdata\\roaming\\python\\python38\\site-packages (from jsonschema>=3.0->altair<6.0,>=4.2.0->gradio) (0.20.0)\n",
      "Requirement already satisfied: six>=1.5 in c:\\anaconda3\\envs\\cv2\\lib\\site-packages (from python-dateutil>=2.7->matplotlib~=3.0->gradio) (1.16.0)\n",
      "Requirement already satisfied: markdown-it-py>=2.2.0 in c:\\users\\shjung\\appdata\\roaming\\python\\python38\\site-packages (from rich>=10.11.0->typer<1.0,>=0.9->typer[all]<1.0,>=0.9->gradio) (3.0.0)\n",
      "Requirement already satisfied: pygments<3.0.0,>=2.13.0 in c:\\anaconda3\\envs\\cv2\\lib\\site-packages (from rich>=10.11.0->typer<1.0,>=0.9->typer[all]<1.0,>=0.9->gradio) (2.15.1)\n",
      "Requirement already satisfied: exceptiongroup>=1.0.2 in c:\\anaconda3\\envs\\cv2\\lib\\site-packages (from anyio->httpx->gradio) (1.2.2)\n",
      "Requirement already satisfied: charset-normalizer<4,>=2 in c:\\anaconda3\\envs\\cv2\\lib\\site-packages (from requests->huggingface-hub>=0.19.3->gradio) (3.3.2)\n",
      "Requirement already satisfied: urllib3<3,>=1.21.1 in c:\\anaconda3\\envs\\cv2\\lib\\site-packages (from requests->huggingface-hub>=0.19.3->gradio) (2.2.2)\n",
      "Requirement already satisfied: mdurl~=0.1 in c:\\users\\shjung\\appdata\\roaming\\python\\python38\\site-packages (from markdown-it-py>=2.2.0->rich>=10.11.0->typer<1.0,>=0.9->typer[all]<1.0,>=0.9->gradio) (0.1.2)\n"
     ]
    },
    {
     "name": "stderr",
     "output_type": "stream",
     "text": [
      "WARNING: typer 0.12.5 does not provide the extra 'all'\n"
     ]
    }
   ],
   "source": [
    "!pip install gradio"
   ]
  },
  {
   "cell_type": "code",
   "execution_count": 3,
   "metadata": {},
   "outputs": [
    {
     "name": "stdout",
     "output_type": "stream",
     "text": [
      "Running on local URL:  http://127.0.0.1:7861\n",
      "IMPORTANT: You are using gradio version 4.10.0, however version 4.29.0 is available, please upgrade.\n",
      "--------\n",
      "Running on public URL: https://fa344c1a2708b0656b.gradio.live\n",
      "\n",
      "This share link expires in 72 hours. For free permanent hosting and GPU upgrades, run `gradio deploy` from Terminal to deploy to Spaces (https://huggingface.co/spaces)\n"
     ]
    },
    {
     "data": {
      "text/html": [
       "<div><iframe src=\"https://fa344c1a2708b0656b.gradio.live\" width=\"100%\" height=\"500\" allow=\"autoplay; camera; microphone; clipboard-read; clipboard-write;\" frameborder=\"0\" allowfullscreen></iframe></div>"
      ],
      "text/plain": [
       "<IPython.core.display.HTML object>"
      ]
     },
     "metadata": {},
     "output_type": "display_data"
    },
    {
     "name": "stderr",
     "output_type": "stream",
     "text": [
      "ERROR:    Exception in ASGI application\n",
      "Traceback (most recent call last):\n",
      "  File \"c:\\anaconda3\\envs\\cv2\\lib\\site-packages\\pydantic\\type_adapter.py\", line 270, in _init_core_attrs\n",
      "    self._core_schema = _getattr_no_parents(self._type, '__pydantic_core_schema__')\n",
      "  File \"c:\\anaconda3\\envs\\cv2\\lib\\site-packages\\pydantic\\type_adapter.py\", line 112, in _getattr_no_parents\n",
      "    raise AttributeError(attribute)\n",
      "AttributeError: __pydantic_core_schema__\n",
      "\n",
      "During handling of the above exception, another exception occurred:\n",
      "\n",
      "Traceback (most recent call last):\n",
      "  File \"C:\\Users\\shjung\\AppData\\Roaming\\Python\\Python38\\site-packages\\uvicorn\\protocols\\http\\h11_impl.py\", line 406, in run_asgi\n",
      "    result = await app(  # type: ignore[func-returns-value]\n",
      "  File \"C:\\Users\\shjung\\AppData\\Roaming\\Python\\Python38\\site-packages\\uvicorn\\middleware\\proxy_headers.py\", line 70, in __call__\n",
      "    return await self.app(scope, receive, send)\n",
      "  File \"C:\\Users\\shjung\\AppData\\Roaming\\Python\\Python38\\site-packages\\fastapi\\applications.py\", line 1054, in __call__\n",
      "    await super().__call__(scope, receive, send)\n",
      "  File \"C:\\Users\\shjung\\AppData\\Roaming\\Python\\Python38\\site-packages\\starlette\\applications.py\", line 113, in __call__\n",
      "    await self.middleware_stack(scope, receive, send)\n",
      "  File \"C:\\Users\\shjung\\AppData\\Roaming\\Python\\Python38\\site-packages\\starlette\\middleware\\errors.py\", line 187, in __call__\n",
      "    raise exc\n",
      "  File \"C:\\Users\\shjung\\AppData\\Roaming\\Python\\Python38\\site-packages\\starlette\\middleware\\errors.py\", line 165, in __call__\n",
      "    await self.app(scope, receive, _send)\n",
      "  File \"C:\\Users\\shjung\\AppData\\Roaming\\Python\\Python38\\site-packages\\starlette\\middleware\\cors.py\", line 93, in __call__\n",
      "    await self.simple_response(scope, receive, send, request_headers=headers)\n",
      "  File \"C:\\Users\\shjung\\AppData\\Roaming\\Python\\Python38\\site-packages\\starlette\\middleware\\cors.py\", line 144, in simple_response\n",
      "    await self.app(scope, receive, send)\n",
      "  File \"C:\\Users\\shjung\\AppData\\Roaming\\Python\\Python38\\site-packages\\starlette\\middleware\\exceptions.py\", line 62, in __call__\n",
      "    await wrap_app_handling_exceptions(self.app, conn)(scope, receive, send)\n",
      "  File \"C:\\Users\\shjung\\AppData\\Roaming\\Python\\Python38\\site-packages\\starlette\\_exception_handler.py\", line 62, in wrapped_app\n",
      "    raise exc\n",
      "  File \"C:\\Users\\shjung\\AppData\\Roaming\\Python\\Python38\\site-packages\\starlette\\_exception_handler.py\", line 51, in wrapped_app\n",
      "    await app(scope, receive, sender)\n",
      "  File \"C:\\Users\\shjung\\AppData\\Roaming\\Python\\Python38\\site-packages\\starlette\\routing.py\", line 715, in __call__\n",
      "    await self.middleware_stack(scope, receive, send)\n",
      "  File \"C:\\Users\\shjung\\AppData\\Roaming\\Python\\Python38\\site-packages\\starlette\\routing.py\", line 735, in app\n",
      "    await route.handle(scope, receive, send)\n",
      "  File \"C:\\Users\\shjung\\AppData\\Roaming\\Python\\Python38\\site-packages\\starlette\\routing.py\", line 288, in handle\n",
      "    await self.app(scope, receive, send)\n",
      "  File \"C:\\Users\\shjung\\AppData\\Roaming\\Python\\Python38\\site-packages\\starlette\\routing.py\", line 76, in app\n",
      "    await wrap_app_handling_exceptions(app, request)(scope, receive, send)\n",
      "  File \"C:\\Users\\shjung\\AppData\\Roaming\\Python\\Python38\\site-packages\\starlette\\_exception_handler.py\", line 62, in wrapped_app\n",
      "    raise exc\n",
      "  File \"C:\\Users\\shjung\\AppData\\Roaming\\Python\\Python38\\site-packages\\starlette\\_exception_handler.py\", line 51, in wrapped_app\n",
      "    await app(scope, receive, sender)\n",
      "  File \"C:\\Users\\shjung\\AppData\\Roaming\\Python\\Python38\\site-packages\\starlette\\routing.py\", line 73, in app\n",
      "    response = await f(request)\n",
      "  File \"C:\\Users\\shjung\\AppData\\Roaming\\Python\\Python38\\site-packages\\fastapi\\routing.py\", line 291, in app\n",
      "    solved_result = await solve_dependencies(\n",
      "  File \"C:\\Users\\shjung\\AppData\\Roaming\\Python\\Python38\\site-packages\\fastapi\\dependencies\\utils.py\", line 656, in solve_dependencies\n",
      "    ) = await request_body_to_args(  # body_params checked above\n",
      "  File \"C:\\Users\\shjung\\AppData\\Roaming\\Python\\Python38\\site-packages\\fastapi\\dependencies\\utils.py\", line 881, in request_body_to_args\n",
      "    fields_to_extract = get_cached_model_fields(first_field.type_)\n",
      "  File \"C:\\Users\\shjung\\AppData\\Roaming\\Python\\Python38\\site-packages\\fastapi\\_compat.py\", line 657, in get_cached_model_fields\n",
      "    return get_model_fields(model)\n",
      "  File \"C:\\Users\\shjung\\AppData\\Roaming\\Python\\Python38\\site-packages\\fastapi\\_compat.py\", line 284, in get_model_fields\n",
      "    return [\n",
      "  File \"C:\\Users\\shjung\\AppData\\Roaming\\Python\\Python38\\site-packages\\fastapi\\_compat.py\", line 285, in <listcomp>\n",
      "    ModelField(field_info=field_info, name=name)\n",
      "  File \"<string>\", line 6, in __init__\n",
      "  File \"C:\\Users\\shjung\\AppData\\Roaming\\Python\\Python38\\site-packages\\fastapi\\_compat.py\", line 110, in __post_init__\n",
      "    self._type_adapter: TypeAdapter[Any] = TypeAdapter(\n",
      "  File \"c:\\anaconda3\\envs\\cv2\\lib\\site-packages\\pydantic\\type_adapter.py\", line 257, in __init__\n",
      "    self._init_core_attrs(rebuild_mocks=False)\n",
      "  File \"c:\\anaconda3\\envs\\cv2\\lib\\site-packages\\pydantic\\type_adapter.py\", line 135, in wrapped\n",
      "    return func(self, *args, **kwargs)\n",
      "  File \"c:\\anaconda3\\envs\\cv2\\lib\\site-packages\\pydantic\\type_adapter.py\", line 277, in _init_core_attrs\n",
      "    self._core_schema = _get_schema(self._type, config_wrapper, parent_depth=self._parent_depth)\n",
      "  File \"c:\\anaconda3\\envs\\cv2\\lib\\site-packages\\pydantic\\type_adapter.py\", line 95, in _get_schema\n",
      "    schema = gen.generate_schema(type_)\n",
      "  File \"c:\\anaconda3\\envs\\cv2\\lib\\site-packages\\pydantic\\_internal\\_generate_schema.py\", line 655, in generate_schema\n",
      "    schema = self._generate_schema_inner(obj)\n",
      "  File \"c:\\anaconda3\\envs\\cv2\\lib\\site-packages\\pydantic\\_internal\\_generate_schema.py\", line 908, in _generate_schema_inner\n",
      "    return self._annotated_schema(obj)\n",
      "  File \"c:\\anaconda3\\envs\\cv2\\lib\\site-packages\\pydantic\\_internal\\_generate_schema.py\", line 2028, in _annotated_schema\n",
      "    schema = self._apply_annotations(source_type, annotations)\n",
      "  File \"c:\\anaconda3\\envs\\cv2\\lib\\site-packages\\pydantic\\_internal\\_generate_schema.py\", line 2107, in _apply_annotations\n",
      "    schema = get_inner_schema(source_type)\n",
      "  File \"c:\\anaconda3\\envs\\cv2\\lib\\site-packages\\pydantic\\_internal\\_schema_generation_shared.py\", line 83, in __call__\n",
      "    schema = self._handler(source_type)\n",
      "  File \"c:\\anaconda3\\envs\\cv2\\lib\\site-packages\\pydantic\\_internal\\_generate_schema.py\", line 2189, in new_handler\n",
      "    schema = metadata_get_schema(source, get_inner_schema)\n",
      "  File \"c:\\anaconda3\\envs\\cv2\\lib\\site-packages\\pydantic\\_internal\\_generate_schema.py\", line 2185, in <lambda>\n",
      "    lambda source, handler: handler(source)\n",
      "  File \"c:\\anaconda3\\envs\\cv2\\lib\\site-packages\\pydantic\\_internal\\_schema_generation_shared.py\", line 83, in __call__\n",
      "    schema = self._handler(source_type)\n",
      "  File \"c:\\anaconda3\\envs\\cv2\\lib\\site-packages\\pydantic\\_internal\\_generate_schema.py\", line 2088, in inner_handler\n",
      "    schema = self._generate_schema_inner(obj)\n",
      "  File \"c:\\anaconda3\\envs\\cv2\\lib\\site-packages\\pydantic\\_internal\\_generate_schema.py\", line 929, in _generate_schema_inner\n",
      "    return self.match_type(obj)\n",
      "  File \"c:\\anaconda3\\envs\\cv2\\lib\\site-packages\\pydantic\\_internal\\_generate_schema.py\", line 1029, in match_type\n",
      "    return self._match_generic_type(obj, origin)\n",
      "  File \"c:\\anaconda3\\envs\\cv2\\lib\\site-packages\\pydantic\\_internal\\_generate_schema.py\", line 1058, in _match_generic_type\n",
      "    return self._union_schema(obj)\n",
      "  File \"c:\\anaconda3\\envs\\cv2\\lib\\site-packages\\pydantic\\_internal\\_generate_schema.py\", line 1378, in _union_schema\n",
      "    choices.append(self.generate_schema(arg))\n",
      "  File \"c:\\anaconda3\\envs\\cv2\\lib\\site-packages\\pydantic\\_internal\\_generate_schema.py\", line 655, in generate_schema\n",
      "    schema = self._generate_schema_inner(obj)\n",
      "  File \"c:\\anaconda3\\envs\\cv2\\lib\\site-packages\\pydantic\\_internal\\_generate_schema.py\", line 929, in _generate_schema_inner\n",
      "    return self.match_type(obj)\n",
      "  File \"c:\\anaconda3\\envs\\cv2\\lib\\site-packages\\pydantic\\_internal\\_generate_schema.py\", line 1038, in match_type\n",
      "    return self._unknown_type_schema(obj)\n",
      "  File \"c:\\anaconda3\\envs\\cv2\\lib\\site-packages\\pydantic\\_internal\\_generate_schema.py\", line 558, in _unknown_type_schema\n",
      "    raise PydanticSchemaGenerationError(\n",
      "pydantic.errors.PydanticSchemaGenerationError: Unable to generate pydantic-core schema for <class 'starlette.requests.Request'>. Set `arbitrary_types_allowed=True` in the model_config to ignore this error or implement `__get_pydantic_core_schema__` on your type to fully support it.\n",
      "\n",
      "If you got this error by calling handler(<some type>) within `__get_pydantic_core_schema__` then you likely need to call `handler.generate_schema(<some type>)` since we do not call `__get_pydantic_core_schema__` on `<some type>` otherwise to avoid infinite recursion.\n",
      "\n",
      "For further information visit https://errors.pydantic.dev/2.9/u/schema-for-unknown-type\n",
      "ERROR:    Exception in ASGI application\n",
      "Traceback (most recent call last):\n",
      "  File \"c:\\anaconda3\\envs\\cv2\\lib\\site-packages\\pydantic\\type_adapter.py\", line 270, in _init_core_attrs\n",
      "    self._core_schema = _getattr_no_parents(self._type, '__pydantic_core_schema__')\n",
      "  File \"c:\\anaconda3\\envs\\cv2\\lib\\site-packages\\pydantic\\type_adapter.py\", line 112, in _getattr_no_parents\n",
      "    raise AttributeError(attribute)\n",
      "AttributeError: __pydantic_core_schema__\n",
      "\n",
      "During handling of the above exception, another exception occurred:\n",
      "\n",
      "Traceback (most recent call last):\n",
      "  File \"C:\\Users\\shjung\\AppData\\Roaming\\Python\\Python38\\site-packages\\uvicorn\\protocols\\http\\h11_impl.py\", line 406, in run_asgi\n",
      "    result = await app(  # type: ignore[func-returns-value]\n",
      "  File \"C:\\Users\\shjung\\AppData\\Roaming\\Python\\Python38\\site-packages\\uvicorn\\middleware\\proxy_headers.py\", line 70, in __call__\n",
      "    return await self.app(scope, receive, send)\n",
      "  File \"C:\\Users\\shjung\\AppData\\Roaming\\Python\\Python38\\site-packages\\fastapi\\applications.py\", line 1054, in __call__\n",
      "    await super().__call__(scope, receive, send)\n",
      "  File \"C:\\Users\\shjung\\AppData\\Roaming\\Python\\Python38\\site-packages\\starlette\\applications.py\", line 113, in __call__\n",
      "    await self.middleware_stack(scope, receive, send)\n",
      "  File \"C:\\Users\\shjung\\AppData\\Roaming\\Python\\Python38\\site-packages\\starlette\\middleware\\errors.py\", line 187, in __call__\n",
      "    raise exc\n",
      "  File \"C:\\Users\\shjung\\AppData\\Roaming\\Python\\Python38\\site-packages\\starlette\\middleware\\errors.py\", line 165, in __call__\n",
      "    await self.app(scope, receive, _send)\n",
      "  File \"C:\\Users\\shjung\\AppData\\Roaming\\Python\\Python38\\site-packages\\starlette\\middleware\\cors.py\", line 93, in __call__\n",
      "    await self.simple_response(scope, receive, send, request_headers=headers)\n",
      "  File \"C:\\Users\\shjung\\AppData\\Roaming\\Python\\Python38\\site-packages\\starlette\\middleware\\cors.py\", line 144, in simple_response\n",
      "    await self.app(scope, receive, send)\n",
      "  File \"C:\\Users\\shjung\\AppData\\Roaming\\Python\\Python38\\site-packages\\starlette\\middleware\\exceptions.py\", line 62, in __call__\n",
      "    await wrap_app_handling_exceptions(self.app, conn)(scope, receive, send)\n",
      "  File \"C:\\Users\\shjung\\AppData\\Roaming\\Python\\Python38\\site-packages\\starlette\\_exception_handler.py\", line 62, in wrapped_app\n",
      "    raise exc\n",
      "  File \"C:\\Users\\shjung\\AppData\\Roaming\\Python\\Python38\\site-packages\\starlette\\_exception_handler.py\", line 51, in wrapped_app\n",
      "    await app(scope, receive, sender)\n",
      "  File \"C:\\Users\\shjung\\AppData\\Roaming\\Python\\Python38\\site-packages\\starlette\\routing.py\", line 715, in __call__\n",
      "    await self.middleware_stack(scope, receive, send)\n",
      "  File \"C:\\Users\\shjung\\AppData\\Roaming\\Python\\Python38\\site-packages\\starlette\\routing.py\", line 735, in app\n",
      "    await route.handle(scope, receive, send)\n",
      "  File \"C:\\Users\\shjung\\AppData\\Roaming\\Python\\Python38\\site-packages\\starlette\\routing.py\", line 288, in handle\n",
      "    await self.app(scope, receive, send)\n",
      "  File \"C:\\Users\\shjung\\AppData\\Roaming\\Python\\Python38\\site-packages\\starlette\\routing.py\", line 76, in app\n",
      "    await wrap_app_handling_exceptions(app, request)(scope, receive, send)\n",
      "  File \"C:\\Users\\shjung\\AppData\\Roaming\\Python\\Python38\\site-packages\\starlette\\_exception_handler.py\", line 62, in wrapped_app\n",
      "    raise exc\n",
      "  File \"C:\\Users\\shjung\\AppData\\Roaming\\Python\\Python38\\site-packages\\starlette\\_exception_handler.py\", line 51, in wrapped_app\n",
      "    await app(scope, receive, sender)\n",
      "  File \"C:\\Users\\shjung\\AppData\\Roaming\\Python\\Python38\\site-packages\\starlette\\routing.py\", line 73, in app\n",
      "    response = await f(request)\n",
      "  File \"C:\\Users\\shjung\\AppData\\Roaming\\Python\\Python38\\site-packages\\fastapi\\routing.py\", line 291, in app\n",
      "    solved_result = await solve_dependencies(\n",
      "  File \"C:\\Users\\shjung\\AppData\\Roaming\\Python\\Python38\\site-packages\\fastapi\\dependencies\\utils.py\", line 656, in solve_dependencies\n",
      "    ) = await request_body_to_args(  # body_params checked above\n",
      "  File \"C:\\Users\\shjung\\AppData\\Roaming\\Python\\Python38\\site-packages\\fastapi\\dependencies\\utils.py\", line 881, in request_body_to_args\n",
      "    fields_to_extract = get_cached_model_fields(first_field.type_)\n",
      "  File \"C:\\Users\\shjung\\AppData\\Roaming\\Python\\Python38\\site-packages\\fastapi\\_compat.py\", line 657, in get_cached_model_fields\n",
      "    return get_model_fields(model)\n",
      "  File \"C:\\Users\\shjung\\AppData\\Roaming\\Python\\Python38\\site-packages\\fastapi\\_compat.py\", line 284, in get_model_fields\n",
      "    return [\n",
      "  File \"C:\\Users\\shjung\\AppData\\Roaming\\Python\\Python38\\site-packages\\fastapi\\_compat.py\", line 285, in <listcomp>\n",
      "    ModelField(field_info=field_info, name=name)\n",
      "  File \"<string>\", line 6, in __init__\n",
      "  File \"C:\\Users\\shjung\\AppData\\Roaming\\Python\\Python38\\site-packages\\fastapi\\_compat.py\", line 110, in __post_init__\n",
      "    self._type_adapter: TypeAdapter[Any] = TypeAdapter(\n",
      "  File \"c:\\anaconda3\\envs\\cv2\\lib\\site-packages\\pydantic\\type_adapter.py\", line 257, in __init__\n",
      "    self._init_core_attrs(rebuild_mocks=False)\n",
      "  File \"c:\\anaconda3\\envs\\cv2\\lib\\site-packages\\pydantic\\type_adapter.py\", line 135, in wrapped\n",
      "    return func(self, *args, **kwargs)\n",
      "  File \"c:\\anaconda3\\envs\\cv2\\lib\\site-packages\\pydantic\\type_adapter.py\", line 277, in _init_core_attrs\n",
      "    self._core_schema = _get_schema(self._type, config_wrapper, parent_depth=self._parent_depth)\n",
      "  File \"c:\\anaconda3\\envs\\cv2\\lib\\site-packages\\pydantic\\type_adapter.py\", line 95, in _get_schema\n",
      "    schema = gen.generate_schema(type_)\n",
      "  File \"c:\\anaconda3\\envs\\cv2\\lib\\site-packages\\pydantic\\_internal\\_generate_schema.py\", line 655, in generate_schema\n",
      "    schema = self._generate_schema_inner(obj)\n",
      "  File \"c:\\anaconda3\\envs\\cv2\\lib\\site-packages\\pydantic\\_internal\\_generate_schema.py\", line 908, in _generate_schema_inner\n",
      "    return self._annotated_schema(obj)\n",
      "  File \"c:\\anaconda3\\envs\\cv2\\lib\\site-packages\\pydantic\\_internal\\_generate_schema.py\", line 2028, in _annotated_schema\n",
      "    schema = self._apply_annotations(source_type, annotations)\n",
      "  File \"c:\\anaconda3\\envs\\cv2\\lib\\site-packages\\pydantic\\_internal\\_generate_schema.py\", line 2107, in _apply_annotations\n",
      "    schema = get_inner_schema(source_type)\n",
      "  File \"c:\\anaconda3\\envs\\cv2\\lib\\site-packages\\pydantic\\_internal\\_schema_generation_shared.py\", line 83, in __call__\n",
      "    schema = self._handler(source_type)\n",
      "  File \"c:\\anaconda3\\envs\\cv2\\lib\\site-packages\\pydantic\\_internal\\_generate_schema.py\", line 2189, in new_handler\n",
      "    schema = metadata_get_schema(source, get_inner_schema)\n",
      "  File \"c:\\anaconda3\\envs\\cv2\\lib\\site-packages\\pydantic\\_internal\\_generate_schema.py\", line 2185, in <lambda>\n",
      "    lambda source, handler: handler(source)\n",
      "  File \"c:\\anaconda3\\envs\\cv2\\lib\\site-packages\\pydantic\\_internal\\_schema_generation_shared.py\", line 83, in __call__\n",
      "    schema = self._handler(source_type)\n",
      "  File \"c:\\anaconda3\\envs\\cv2\\lib\\site-packages\\pydantic\\_internal\\_generate_schema.py\", line 2088, in inner_handler\n",
      "    schema = self._generate_schema_inner(obj)\n",
      "  File \"c:\\anaconda3\\envs\\cv2\\lib\\site-packages\\pydantic\\_internal\\_generate_schema.py\", line 929, in _generate_schema_inner\n",
      "    return self.match_type(obj)\n",
      "  File \"c:\\anaconda3\\envs\\cv2\\lib\\site-packages\\pydantic\\_internal\\_generate_schema.py\", line 1029, in match_type\n",
      "    return self._match_generic_type(obj, origin)\n",
      "  File \"c:\\anaconda3\\envs\\cv2\\lib\\site-packages\\pydantic\\_internal\\_generate_schema.py\", line 1058, in _match_generic_type\n",
      "    return self._union_schema(obj)\n",
      "  File \"c:\\anaconda3\\envs\\cv2\\lib\\site-packages\\pydantic\\_internal\\_generate_schema.py\", line 1378, in _union_schema\n",
      "    choices.append(self.generate_schema(arg))\n",
      "  File \"c:\\anaconda3\\envs\\cv2\\lib\\site-packages\\pydantic\\_internal\\_generate_schema.py\", line 655, in generate_schema\n",
      "    schema = self._generate_schema_inner(obj)\n",
      "  File \"c:\\anaconda3\\envs\\cv2\\lib\\site-packages\\pydantic\\_internal\\_generate_schema.py\", line 929, in _generate_schema_inner\n",
      "    return self.match_type(obj)\n",
      "  File \"c:\\anaconda3\\envs\\cv2\\lib\\site-packages\\pydantic\\_internal\\_generate_schema.py\", line 1038, in match_type\n",
      "    return self._unknown_type_schema(obj)\n",
      "  File \"c:\\anaconda3\\envs\\cv2\\lib\\site-packages\\pydantic\\_internal\\_generate_schema.py\", line 558, in _unknown_type_schema\n",
      "    raise PydanticSchemaGenerationError(\n",
      "pydantic.errors.PydanticSchemaGenerationError: Unable to generate pydantic-core schema for <class 'starlette.requests.Request'>. Set `arbitrary_types_allowed=True` in the model_config to ignore this error or implement `__get_pydantic_core_schema__` on your type to fully support it.\n",
      "\n",
      "If you got this error by calling handler(<some type>) within `__get_pydantic_core_schema__` then you likely need to call `handler.generate_schema(<some type>)` since we do not call `__get_pydantic_core_schema__` on `<some type>` otherwise to avoid infinite recursion.\n",
      "\n",
      "For further information visit https://errors.pydantic.dev/2.9/u/schema-for-unknown-type\n",
      "ERROR:    Exception in ASGI application\n",
      "Traceback (most recent call last):\n",
      "  File \"c:\\anaconda3\\envs\\cv2\\lib\\site-packages\\pydantic\\type_adapter.py\", line 270, in _init_core_attrs\n",
      "    self._core_schema = _getattr_no_parents(self._type, '__pydantic_core_schema__')\n",
      "  File \"c:\\anaconda3\\envs\\cv2\\lib\\site-packages\\pydantic\\type_adapter.py\", line 112, in _getattr_no_parents\n",
      "    raise AttributeError(attribute)\n",
      "AttributeError: __pydantic_core_schema__\n",
      "\n",
      "During handling of the above exception, another exception occurred:\n",
      "\n",
      "Traceback (most recent call last):\n",
      "  File \"C:\\Users\\shjung\\AppData\\Roaming\\Python\\Python38\\site-packages\\uvicorn\\protocols\\http\\h11_impl.py\", line 406, in run_asgi\n",
      "    result = await app(  # type: ignore[func-returns-value]\n",
      "  File \"C:\\Users\\shjung\\AppData\\Roaming\\Python\\Python38\\site-packages\\uvicorn\\middleware\\proxy_headers.py\", line 70, in __call__\n",
      "    return await self.app(scope, receive, send)\n",
      "  File \"C:\\Users\\shjung\\AppData\\Roaming\\Python\\Python38\\site-packages\\fastapi\\applications.py\", line 1054, in __call__\n",
      "    await super().__call__(scope, receive, send)\n",
      "  File \"C:\\Users\\shjung\\AppData\\Roaming\\Python\\Python38\\site-packages\\starlette\\applications.py\", line 113, in __call__\n",
      "    await self.middleware_stack(scope, receive, send)\n",
      "  File \"C:\\Users\\shjung\\AppData\\Roaming\\Python\\Python38\\site-packages\\starlette\\middleware\\errors.py\", line 187, in __call__\n",
      "    raise exc\n",
      "  File \"C:\\Users\\shjung\\AppData\\Roaming\\Python\\Python38\\site-packages\\starlette\\middleware\\errors.py\", line 165, in __call__\n",
      "    await self.app(scope, receive, _send)\n",
      "  File \"C:\\Users\\shjung\\AppData\\Roaming\\Python\\Python38\\site-packages\\starlette\\middleware\\cors.py\", line 93, in __call__\n",
      "    await self.simple_response(scope, receive, send, request_headers=headers)\n",
      "  File \"C:\\Users\\shjung\\AppData\\Roaming\\Python\\Python38\\site-packages\\starlette\\middleware\\cors.py\", line 144, in simple_response\n",
      "    await self.app(scope, receive, send)\n",
      "  File \"C:\\Users\\shjung\\AppData\\Roaming\\Python\\Python38\\site-packages\\starlette\\middleware\\exceptions.py\", line 62, in __call__\n",
      "    await wrap_app_handling_exceptions(self.app, conn)(scope, receive, send)\n",
      "  File \"C:\\Users\\shjung\\AppData\\Roaming\\Python\\Python38\\site-packages\\starlette\\_exception_handler.py\", line 62, in wrapped_app\n",
      "    raise exc\n",
      "  File \"C:\\Users\\shjung\\AppData\\Roaming\\Python\\Python38\\site-packages\\starlette\\_exception_handler.py\", line 51, in wrapped_app\n",
      "    await app(scope, receive, sender)\n",
      "  File \"C:\\Users\\shjung\\AppData\\Roaming\\Python\\Python38\\site-packages\\starlette\\routing.py\", line 715, in __call__\n",
      "    await self.middleware_stack(scope, receive, send)\n",
      "  File \"C:\\Users\\shjung\\AppData\\Roaming\\Python\\Python38\\site-packages\\starlette\\routing.py\", line 735, in app\n",
      "    await route.handle(scope, receive, send)\n",
      "  File \"C:\\Users\\shjung\\AppData\\Roaming\\Python\\Python38\\site-packages\\starlette\\routing.py\", line 288, in handle\n",
      "    await self.app(scope, receive, send)\n",
      "  File \"C:\\Users\\shjung\\AppData\\Roaming\\Python\\Python38\\site-packages\\starlette\\routing.py\", line 76, in app\n",
      "    await wrap_app_handling_exceptions(app, request)(scope, receive, send)\n",
      "  File \"C:\\Users\\shjung\\AppData\\Roaming\\Python\\Python38\\site-packages\\starlette\\_exception_handler.py\", line 62, in wrapped_app\n",
      "    raise exc\n",
      "  File \"C:\\Users\\shjung\\AppData\\Roaming\\Python\\Python38\\site-packages\\starlette\\_exception_handler.py\", line 51, in wrapped_app\n",
      "    await app(scope, receive, sender)\n",
      "  File \"C:\\Users\\shjung\\AppData\\Roaming\\Python\\Python38\\site-packages\\starlette\\routing.py\", line 73, in app\n",
      "    response = await f(request)\n",
      "  File \"C:\\Users\\shjung\\AppData\\Roaming\\Python\\Python38\\site-packages\\fastapi\\routing.py\", line 291, in app\n",
      "    solved_result = await solve_dependencies(\n",
      "  File \"C:\\Users\\shjung\\AppData\\Roaming\\Python\\Python38\\site-packages\\fastapi\\dependencies\\utils.py\", line 656, in solve_dependencies\n",
      "    ) = await request_body_to_args(  # body_params checked above\n",
      "  File \"C:\\Users\\shjung\\AppData\\Roaming\\Python\\Python38\\site-packages\\fastapi\\dependencies\\utils.py\", line 881, in request_body_to_args\n",
      "    fields_to_extract = get_cached_model_fields(first_field.type_)\n",
      "  File \"C:\\Users\\shjung\\AppData\\Roaming\\Python\\Python38\\site-packages\\fastapi\\_compat.py\", line 657, in get_cached_model_fields\n",
      "    return get_model_fields(model)\n",
      "  File \"C:\\Users\\shjung\\AppData\\Roaming\\Python\\Python38\\site-packages\\fastapi\\_compat.py\", line 284, in get_model_fields\n",
      "    return [\n",
      "  File \"C:\\Users\\shjung\\AppData\\Roaming\\Python\\Python38\\site-packages\\fastapi\\_compat.py\", line 285, in <listcomp>\n",
      "    ModelField(field_info=field_info, name=name)\n",
      "  File \"<string>\", line 6, in __init__\n",
      "  File \"C:\\Users\\shjung\\AppData\\Roaming\\Python\\Python38\\site-packages\\fastapi\\_compat.py\", line 110, in __post_init__\n",
      "    self._type_adapter: TypeAdapter[Any] = TypeAdapter(\n",
      "  File \"c:\\anaconda3\\envs\\cv2\\lib\\site-packages\\pydantic\\type_adapter.py\", line 257, in __init__\n",
      "    self._init_core_attrs(rebuild_mocks=False)\n",
      "  File \"c:\\anaconda3\\envs\\cv2\\lib\\site-packages\\pydantic\\type_adapter.py\", line 135, in wrapped\n",
      "    return func(self, *args, **kwargs)\n",
      "  File \"c:\\anaconda3\\envs\\cv2\\lib\\site-packages\\pydantic\\type_adapter.py\", line 277, in _init_core_attrs\n",
      "    self._core_schema = _get_schema(self._type, config_wrapper, parent_depth=self._parent_depth)\n",
      "  File \"c:\\anaconda3\\envs\\cv2\\lib\\site-packages\\pydantic\\type_adapter.py\", line 95, in _get_schema\n",
      "    schema = gen.generate_schema(type_)\n",
      "  File \"c:\\anaconda3\\envs\\cv2\\lib\\site-packages\\pydantic\\_internal\\_generate_schema.py\", line 655, in generate_schema\n",
      "    schema = self._generate_schema_inner(obj)\n",
      "  File \"c:\\anaconda3\\envs\\cv2\\lib\\site-packages\\pydantic\\_internal\\_generate_schema.py\", line 908, in _generate_schema_inner\n",
      "    return self._annotated_schema(obj)\n",
      "  File \"c:\\anaconda3\\envs\\cv2\\lib\\site-packages\\pydantic\\_internal\\_generate_schema.py\", line 2028, in _annotated_schema\n",
      "    schema = self._apply_annotations(source_type, annotations)\n",
      "  File \"c:\\anaconda3\\envs\\cv2\\lib\\site-packages\\pydantic\\_internal\\_generate_schema.py\", line 2107, in _apply_annotations\n",
      "    schema = get_inner_schema(source_type)\n",
      "  File \"c:\\anaconda3\\envs\\cv2\\lib\\site-packages\\pydantic\\_internal\\_schema_generation_shared.py\", line 83, in __call__\n",
      "    schema = self._handler(source_type)\n",
      "  File \"c:\\anaconda3\\envs\\cv2\\lib\\site-packages\\pydantic\\_internal\\_generate_schema.py\", line 2189, in new_handler\n",
      "    schema = metadata_get_schema(source, get_inner_schema)\n",
      "  File \"c:\\anaconda3\\envs\\cv2\\lib\\site-packages\\pydantic\\_internal\\_generate_schema.py\", line 2185, in <lambda>\n",
      "    lambda source, handler: handler(source)\n",
      "  File \"c:\\anaconda3\\envs\\cv2\\lib\\site-packages\\pydantic\\_internal\\_schema_generation_shared.py\", line 83, in __call__\n",
      "    schema = self._handler(source_type)\n",
      "  File \"c:\\anaconda3\\envs\\cv2\\lib\\site-packages\\pydantic\\_internal\\_generate_schema.py\", line 2088, in inner_handler\n",
      "    schema = self._generate_schema_inner(obj)\n",
      "  File \"c:\\anaconda3\\envs\\cv2\\lib\\site-packages\\pydantic\\_internal\\_generate_schema.py\", line 929, in _generate_schema_inner\n",
      "    return self.match_type(obj)\n",
      "  File \"c:\\anaconda3\\envs\\cv2\\lib\\site-packages\\pydantic\\_internal\\_generate_schema.py\", line 1029, in match_type\n",
      "    return self._match_generic_type(obj, origin)\n",
      "  File \"c:\\anaconda3\\envs\\cv2\\lib\\site-packages\\pydantic\\_internal\\_generate_schema.py\", line 1058, in _match_generic_type\n",
      "    return self._union_schema(obj)\n",
      "  File \"c:\\anaconda3\\envs\\cv2\\lib\\site-packages\\pydantic\\_internal\\_generate_schema.py\", line 1378, in _union_schema\n",
      "    choices.append(self.generate_schema(arg))\n",
      "  File \"c:\\anaconda3\\envs\\cv2\\lib\\site-packages\\pydantic\\_internal\\_generate_schema.py\", line 655, in generate_schema\n",
      "    schema = self._generate_schema_inner(obj)\n",
      "  File \"c:\\anaconda3\\envs\\cv2\\lib\\site-packages\\pydantic\\_internal\\_generate_schema.py\", line 929, in _generate_schema_inner\n",
      "    return self.match_type(obj)\n",
      "  File \"c:\\anaconda3\\envs\\cv2\\lib\\site-packages\\pydantic\\_internal\\_generate_schema.py\", line 1038, in match_type\n",
      "    return self._unknown_type_schema(obj)\n",
      "  File \"c:\\anaconda3\\envs\\cv2\\lib\\site-packages\\pydantic\\_internal\\_generate_schema.py\", line 558, in _unknown_type_schema\n",
      "    raise PydanticSchemaGenerationError(\n",
      "pydantic.errors.PydanticSchemaGenerationError: Unable to generate pydantic-core schema for <class 'starlette.requests.Request'>. Set `arbitrary_types_allowed=True` in the model_config to ignore this error or implement `__get_pydantic_core_schema__` on your type to fully support it.\n",
      "\n",
      "If you got this error by calling handler(<some type>) within `__get_pydantic_core_schema__` then you likely need to call `handler.generate_schema(<some type>)` since we do not call `__get_pydantic_core_schema__` on `<some type>` otherwise to avoid infinite recursion.\n",
      "\n",
      "For further information visit https://errors.pydantic.dev/2.9/u/schema-for-unknown-type\n",
      "ERROR:    Exception in ASGI application\n",
      "Traceback (most recent call last):\n",
      "  File \"c:\\anaconda3\\envs\\cv2\\lib\\site-packages\\pydantic\\type_adapter.py\", line 270, in _init_core_attrs\n",
      "    self._core_schema = _getattr_no_parents(self._type, '__pydantic_core_schema__')\n",
      "  File \"c:\\anaconda3\\envs\\cv2\\lib\\site-packages\\pydantic\\type_adapter.py\", line 112, in _getattr_no_parents\n",
      "    raise AttributeError(attribute)\n",
      "AttributeError: __pydantic_core_schema__\n",
      "\n",
      "During handling of the above exception, another exception occurred:\n",
      "\n",
      "Traceback (most recent call last):\n",
      "  File \"C:\\Users\\shjung\\AppData\\Roaming\\Python\\Python38\\site-packages\\uvicorn\\protocols\\http\\h11_impl.py\", line 406, in run_asgi\n",
      "    result = await app(  # type: ignore[func-returns-value]\n",
      "  File \"C:\\Users\\shjung\\AppData\\Roaming\\Python\\Python38\\site-packages\\uvicorn\\middleware\\proxy_headers.py\", line 70, in __call__\n",
      "    return await self.app(scope, receive, send)\n",
      "  File \"C:\\Users\\shjung\\AppData\\Roaming\\Python\\Python38\\site-packages\\fastapi\\applications.py\", line 1054, in __call__\n",
      "    await super().__call__(scope, receive, send)\n",
      "  File \"C:\\Users\\shjung\\AppData\\Roaming\\Python\\Python38\\site-packages\\starlette\\applications.py\", line 113, in __call__\n",
      "    await self.middleware_stack(scope, receive, send)\n",
      "  File \"C:\\Users\\shjung\\AppData\\Roaming\\Python\\Python38\\site-packages\\starlette\\middleware\\errors.py\", line 187, in __call__\n",
      "    raise exc\n",
      "  File \"C:\\Users\\shjung\\AppData\\Roaming\\Python\\Python38\\site-packages\\starlette\\middleware\\errors.py\", line 165, in __call__\n",
      "    await self.app(scope, receive, _send)\n",
      "  File \"C:\\Users\\shjung\\AppData\\Roaming\\Python\\Python38\\site-packages\\starlette\\middleware\\cors.py\", line 93, in __call__\n",
      "    await self.simple_response(scope, receive, send, request_headers=headers)\n",
      "  File \"C:\\Users\\shjung\\AppData\\Roaming\\Python\\Python38\\site-packages\\starlette\\middleware\\cors.py\", line 144, in simple_response\n",
      "    await self.app(scope, receive, send)\n",
      "  File \"C:\\Users\\shjung\\AppData\\Roaming\\Python\\Python38\\site-packages\\starlette\\middleware\\exceptions.py\", line 62, in __call__\n",
      "    await wrap_app_handling_exceptions(self.app, conn)(scope, receive, send)\n",
      "  File \"C:\\Users\\shjung\\AppData\\Roaming\\Python\\Python38\\site-packages\\starlette\\_exception_handler.py\", line 62, in wrapped_app\n",
      "    raise exc\n",
      "  File \"C:\\Users\\shjung\\AppData\\Roaming\\Python\\Python38\\site-packages\\starlette\\_exception_handler.py\", line 51, in wrapped_app\n",
      "    await app(scope, receive, sender)\n",
      "  File \"C:\\Users\\shjung\\AppData\\Roaming\\Python\\Python38\\site-packages\\starlette\\routing.py\", line 715, in __call__\n",
      "    await self.middleware_stack(scope, receive, send)\n",
      "  File \"C:\\Users\\shjung\\AppData\\Roaming\\Python\\Python38\\site-packages\\starlette\\routing.py\", line 735, in app\n",
      "    await route.handle(scope, receive, send)\n",
      "  File \"C:\\Users\\shjung\\AppData\\Roaming\\Python\\Python38\\site-packages\\starlette\\routing.py\", line 288, in handle\n",
      "    await self.app(scope, receive, send)\n",
      "  File \"C:\\Users\\shjung\\AppData\\Roaming\\Python\\Python38\\site-packages\\starlette\\routing.py\", line 76, in app\n",
      "    await wrap_app_handling_exceptions(app, request)(scope, receive, send)\n",
      "  File \"C:\\Users\\shjung\\AppData\\Roaming\\Python\\Python38\\site-packages\\starlette\\_exception_handler.py\", line 62, in wrapped_app\n",
      "    raise exc\n",
      "  File \"C:\\Users\\shjung\\AppData\\Roaming\\Python\\Python38\\site-packages\\starlette\\_exception_handler.py\", line 51, in wrapped_app\n",
      "    await app(scope, receive, sender)\n",
      "  File \"C:\\Users\\shjung\\AppData\\Roaming\\Python\\Python38\\site-packages\\starlette\\routing.py\", line 73, in app\n",
      "    response = await f(request)\n",
      "  File \"C:\\Users\\shjung\\AppData\\Roaming\\Python\\Python38\\site-packages\\fastapi\\routing.py\", line 291, in app\n",
      "    solved_result = await solve_dependencies(\n",
      "  File \"C:\\Users\\shjung\\AppData\\Roaming\\Python\\Python38\\site-packages\\fastapi\\dependencies\\utils.py\", line 656, in solve_dependencies\n",
      "    ) = await request_body_to_args(  # body_params checked above\n",
      "  File \"C:\\Users\\shjung\\AppData\\Roaming\\Python\\Python38\\site-packages\\fastapi\\dependencies\\utils.py\", line 881, in request_body_to_args\n",
      "    fields_to_extract = get_cached_model_fields(first_field.type_)\n",
      "  File \"C:\\Users\\shjung\\AppData\\Roaming\\Python\\Python38\\site-packages\\fastapi\\_compat.py\", line 657, in get_cached_model_fields\n",
      "    return get_model_fields(model)\n",
      "  File \"C:\\Users\\shjung\\AppData\\Roaming\\Python\\Python38\\site-packages\\fastapi\\_compat.py\", line 284, in get_model_fields\n",
      "    return [\n",
      "  File \"C:\\Users\\shjung\\AppData\\Roaming\\Python\\Python38\\site-packages\\fastapi\\_compat.py\", line 285, in <listcomp>\n",
      "    ModelField(field_info=field_info, name=name)\n",
      "  File \"<string>\", line 6, in __init__\n",
      "  File \"C:\\Users\\shjung\\AppData\\Roaming\\Python\\Python38\\site-packages\\fastapi\\_compat.py\", line 110, in __post_init__\n",
      "    self._type_adapter: TypeAdapter[Any] = TypeAdapter(\n",
      "  File \"c:\\anaconda3\\envs\\cv2\\lib\\site-packages\\pydantic\\type_adapter.py\", line 257, in __init__\n",
      "    self._init_core_attrs(rebuild_mocks=False)\n",
      "  File \"c:\\anaconda3\\envs\\cv2\\lib\\site-packages\\pydantic\\type_adapter.py\", line 135, in wrapped\n",
      "    return func(self, *args, **kwargs)\n",
      "  File \"c:\\anaconda3\\envs\\cv2\\lib\\site-packages\\pydantic\\type_adapter.py\", line 277, in _init_core_attrs\n",
      "    self._core_schema = _get_schema(self._type, config_wrapper, parent_depth=self._parent_depth)\n",
      "  File \"c:\\anaconda3\\envs\\cv2\\lib\\site-packages\\pydantic\\type_adapter.py\", line 95, in _get_schema\n",
      "    schema = gen.generate_schema(type_)\n",
      "  File \"c:\\anaconda3\\envs\\cv2\\lib\\site-packages\\pydantic\\_internal\\_generate_schema.py\", line 655, in generate_schema\n",
      "    schema = self._generate_schema_inner(obj)\n",
      "  File \"c:\\anaconda3\\envs\\cv2\\lib\\site-packages\\pydantic\\_internal\\_generate_schema.py\", line 908, in _generate_schema_inner\n",
      "    return self._annotated_schema(obj)\n",
      "  File \"c:\\anaconda3\\envs\\cv2\\lib\\site-packages\\pydantic\\_internal\\_generate_schema.py\", line 2028, in _annotated_schema\n",
      "    schema = self._apply_annotations(source_type, annotations)\n",
      "  File \"c:\\anaconda3\\envs\\cv2\\lib\\site-packages\\pydantic\\_internal\\_generate_schema.py\", line 2107, in _apply_annotations\n",
      "    schema = get_inner_schema(source_type)\n",
      "  File \"c:\\anaconda3\\envs\\cv2\\lib\\site-packages\\pydantic\\_internal\\_schema_generation_shared.py\", line 83, in __call__\n",
      "    schema = self._handler(source_type)\n",
      "  File \"c:\\anaconda3\\envs\\cv2\\lib\\site-packages\\pydantic\\_internal\\_generate_schema.py\", line 2189, in new_handler\n",
      "    schema = metadata_get_schema(source, get_inner_schema)\n",
      "  File \"c:\\anaconda3\\envs\\cv2\\lib\\site-packages\\pydantic\\_internal\\_generate_schema.py\", line 2185, in <lambda>\n",
      "    lambda source, handler: handler(source)\n",
      "  File \"c:\\anaconda3\\envs\\cv2\\lib\\site-packages\\pydantic\\_internal\\_schema_generation_shared.py\", line 83, in __call__\n",
      "    schema = self._handler(source_type)\n",
      "  File \"c:\\anaconda3\\envs\\cv2\\lib\\site-packages\\pydantic\\_internal\\_generate_schema.py\", line 2088, in inner_handler\n",
      "    schema = self._generate_schema_inner(obj)\n",
      "  File \"c:\\anaconda3\\envs\\cv2\\lib\\site-packages\\pydantic\\_internal\\_generate_schema.py\", line 929, in _generate_schema_inner\n",
      "    return self.match_type(obj)\n",
      "  File \"c:\\anaconda3\\envs\\cv2\\lib\\site-packages\\pydantic\\_internal\\_generate_schema.py\", line 1029, in match_type\n",
      "    return self._match_generic_type(obj, origin)\n",
      "  File \"c:\\anaconda3\\envs\\cv2\\lib\\site-packages\\pydantic\\_internal\\_generate_schema.py\", line 1058, in _match_generic_type\n",
      "    return self._union_schema(obj)\n",
      "  File \"c:\\anaconda3\\envs\\cv2\\lib\\site-packages\\pydantic\\_internal\\_generate_schema.py\", line 1378, in _union_schema\n",
      "    choices.append(self.generate_schema(arg))\n",
      "  File \"c:\\anaconda3\\envs\\cv2\\lib\\site-packages\\pydantic\\_internal\\_generate_schema.py\", line 655, in generate_schema\n",
      "    schema = self._generate_schema_inner(obj)\n",
      "  File \"c:\\anaconda3\\envs\\cv2\\lib\\site-packages\\pydantic\\_internal\\_generate_schema.py\", line 929, in _generate_schema_inner\n",
      "    return self.match_type(obj)\n",
      "  File \"c:\\anaconda3\\envs\\cv2\\lib\\site-packages\\pydantic\\_internal\\_generate_schema.py\", line 1038, in match_type\n",
      "    return self._unknown_type_schema(obj)\n",
      "  File \"c:\\anaconda3\\envs\\cv2\\lib\\site-packages\\pydantic\\_internal\\_generate_schema.py\", line 558, in _unknown_type_schema\n",
      "    raise PydanticSchemaGenerationError(\n",
      "pydantic.errors.PydanticSchemaGenerationError: Unable to generate pydantic-core schema for <class 'starlette.requests.Request'>. Set `arbitrary_types_allowed=True` in the model_config to ignore this error or implement `__get_pydantic_core_schema__` on your type to fully support it.\n",
      "\n",
      "If you got this error by calling handler(<some type>) within `__get_pydantic_core_schema__` then you likely need to call `handler.generate_schema(<some type>)` since we do not call `__get_pydantic_core_schema__` on `<some type>` otherwise to avoid infinite recursion.\n",
      "\n",
      "For further information visit https://errors.pydantic.dev/2.9/u/schema-for-unknown-type\n",
      "ERROR:    Exception in ASGI application\n",
      "Traceback (most recent call last):\n",
      "  File \"c:\\anaconda3\\envs\\cv2\\lib\\site-packages\\pydantic\\type_adapter.py\", line 270, in _init_core_attrs\n",
      "    self._core_schema = _getattr_no_parents(self._type, '__pydantic_core_schema__')\n",
      "  File \"c:\\anaconda3\\envs\\cv2\\lib\\site-packages\\pydantic\\type_adapter.py\", line 112, in _getattr_no_parents\n",
      "    raise AttributeError(attribute)\n",
      "AttributeError: __pydantic_core_schema__\n",
      "\n",
      "During handling of the above exception, another exception occurred:\n",
      "\n",
      "Traceback (most recent call last):\n",
      "  File \"C:\\Users\\shjung\\AppData\\Roaming\\Python\\Python38\\site-packages\\uvicorn\\protocols\\http\\h11_impl.py\", line 406, in run_asgi\n",
      "    result = await app(  # type: ignore[func-returns-value]\n",
      "  File \"C:\\Users\\shjung\\AppData\\Roaming\\Python\\Python38\\site-packages\\uvicorn\\middleware\\proxy_headers.py\", line 70, in __call__\n",
      "    return await self.app(scope, receive, send)\n",
      "  File \"C:\\Users\\shjung\\AppData\\Roaming\\Python\\Python38\\site-packages\\fastapi\\applications.py\", line 1054, in __call__\n",
      "    await super().__call__(scope, receive, send)\n",
      "  File \"C:\\Users\\shjung\\AppData\\Roaming\\Python\\Python38\\site-packages\\starlette\\applications.py\", line 113, in __call__\n",
      "    await self.middleware_stack(scope, receive, send)\n",
      "  File \"C:\\Users\\shjung\\AppData\\Roaming\\Python\\Python38\\site-packages\\starlette\\middleware\\errors.py\", line 187, in __call__\n",
      "    raise exc\n",
      "  File \"C:\\Users\\shjung\\AppData\\Roaming\\Python\\Python38\\site-packages\\starlette\\middleware\\errors.py\", line 165, in __call__\n",
      "    await self.app(scope, receive, _send)\n",
      "  File \"C:\\Users\\shjung\\AppData\\Roaming\\Python\\Python38\\site-packages\\starlette\\middleware\\cors.py\", line 93, in __call__\n",
      "    await self.simple_response(scope, receive, send, request_headers=headers)\n",
      "  File \"C:\\Users\\shjung\\AppData\\Roaming\\Python\\Python38\\site-packages\\starlette\\middleware\\cors.py\", line 144, in simple_response\n",
      "    await self.app(scope, receive, send)\n",
      "  File \"C:\\Users\\shjung\\AppData\\Roaming\\Python\\Python38\\site-packages\\starlette\\middleware\\exceptions.py\", line 62, in __call__\n",
      "    await wrap_app_handling_exceptions(self.app, conn)(scope, receive, send)\n",
      "  File \"C:\\Users\\shjung\\AppData\\Roaming\\Python\\Python38\\site-packages\\starlette\\_exception_handler.py\", line 62, in wrapped_app\n",
      "    raise exc\n",
      "  File \"C:\\Users\\shjung\\AppData\\Roaming\\Python\\Python38\\site-packages\\starlette\\_exception_handler.py\", line 51, in wrapped_app\n",
      "    await app(scope, receive, sender)\n",
      "  File \"C:\\Users\\shjung\\AppData\\Roaming\\Python\\Python38\\site-packages\\starlette\\routing.py\", line 715, in __call__\n",
      "    await self.middleware_stack(scope, receive, send)\n",
      "  File \"C:\\Users\\shjung\\AppData\\Roaming\\Python\\Python38\\site-packages\\starlette\\routing.py\", line 735, in app\n",
      "    await route.handle(scope, receive, send)\n",
      "  File \"C:\\Users\\shjung\\AppData\\Roaming\\Python\\Python38\\site-packages\\starlette\\routing.py\", line 288, in handle\n",
      "    await self.app(scope, receive, send)\n",
      "  File \"C:\\Users\\shjung\\AppData\\Roaming\\Python\\Python38\\site-packages\\starlette\\routing.py\", line 76, in app\n",
      "    await wrap_app_handling_exceptions(app, request)(scope, receive, send)\n",
      "  File \"C:\\Users\\shjung\\AppData\\Roaming\\Python\\Python38\\site-packages\\starlette\\_exception_handler.py\", line 62, in wrapped_app\n",
      "    raise exc\n",
      "  File \"C:\\Users\\shjung\\AppData\\Roaming\\Python\\Python38\\site-packages\\starlette\\_exception_handler.py\", line 51, in wrapped_app\n",
      "    await app(scope, receive, sender)\n",
      "  File \"C:\\Users\\shjung\\AppData\\Roaming\\Python\\Python38\\site-packages\\starlette\\routing.py\", line 73, in app\n",
      "    response = await f(request)\n",
      "  File \"C:\\Users\\shjung\\AppData\\Roaming\\Python\\Python38\\site-packages\\fastapi\\routing.py\", line 291, in app\n",
      "    solved_result = await solve_dependencies(\n",
      "  File \"C:\\Users\\shjung\\AppData\\Roaming\\Python\\Python38\\site-packages\\fastapi\\dependencies\\utils.py\", line 656, in solve_dependencies\n",
      "    ) = await request_body_to_args(  # body_params checked above\n",
      "  File \"C:\\Users\\shjung\\AppData\\Roaming\\Python\\Python38\\site-packages\\fastapi\\dependencies\\utils.py\", line 881, in request_body_to_args\n",
      "    fields_to_extract = get_cached_model_fields(first_field.type_)\n",
      "  File \"C:\\Users\\shjung\\AppData\\Roaming\\Python\\Python38\\site-packages\\fastapi\\_compat.py\", line 657, in get_cached_model_fields\n",
      "    return get_model_fields(model)\n",
      "  File \"C:\\Users\\shjung\\AppData\\Roaming\\Python\\Python38\\site-packages\\fastapi\\_compat.py\", line 284, in get_model_fields\n",
      "    return [\n",
      "  File \"C:\\Users\\shjung\\AppData\\Roaming\\Python\\Python38\\site-packages\\fastapi\\_compat.py\", line 285, in <listcomp>\n",
      "    ModelField(field_info=field_info, name=name)\n",
      "  File \"<string>\", line 6, in __init__\n",
      "  File \"C:\\Users\\shjung\\AppData\\Roaming\\Python\\Python38\\site-packages\\fastapi\\_compat.py\", line 110, in __post_init__\n",
      "    self._type_adapter: TypeAdapter[Any] = TypeAdapter(\n",
      "  File \"c:\\anaconda3\\envs\\cv2\\lib\\site-packages\\pydantic\\type_adapter.py\", line 257, in __init__\n",
      "    self._init_core_attrs(rebuild_mocks=False)\n",
      "  File \"c:\\anaconda3\\envs\\cv2\\lib\\site-packages\\pydantic\\type_adapter.py\", line 135, in wrapped\n",
      "    return func(self, *args, **kwargs)\n",
      "  File \"c:\\anaconda3\\envs\\cv2\\lib\\site-packages\\pydantic\\type_adapter.py\", line 277, in _init_core_attrs\n",
      "    self._core_schema = _get_schema(self._type, config_wrapper, parent_depth=self._parent_depth)\n",
      "  File \"c:\\anaconda3\\envs\\cv2\\lib\\site-packages\\pydantic\\type_adapter.py\", line 95, in _get_schema\n",
      "    schema = gen.generate_schema(type_)\n",
      "  File \"c:\\anaconda3\\envs\\cv2\\lib\\site-packages\\pydantic\\_internal\\_generate_schema.py\", line 655, in generate_schema\n",
      "    schema = self._generate_schema_inner(obj)\n",
      "  File \"c:\\anaconda3\\envs\\cv2\\lib\\site-packages\\pydantic\\_internal\\_generate_schema.py\", line 908, in _generate_schema_inner\n",
      "    return self._annotated_schema(obj)\n",
      "  File \"c:\\anaconda3\\envs\\cv2\\lib\\site-packages\\pydantic\\_internal\\_generate_schema.py\", line 2028, in _annotated_schema\n",
      "    schema = self._apply_annotations(source_type, annotations)\n",
      "  File \"c:\\anaconda3\\envs\\cv2\\lib\\site-packages\\pydantic\\_internal\\_generate_schema.py\", line 2107, in _apply_annotations\n",
      "    schema = get_inner_schema(source_type)\n",
      "  File \"c:\\anaconda3\\envs\\cv2\\lib\\site-packages\\pydantic\\_internal\\_schema_generation_shared.py\", line 83, in __call__\n",
      "    schema = self._handler(source_type)\n",
      "  File \"c:\\anaconda3\\envs\\cv2\\lib\\site-packages\\pydantic\\_internal\\_generate_schema.py\", line 2189, in new_handler\n",
      "    schema = metadata_get_schema(source, get_inner_schema)\n",
      "  File \"c:\\anaconda3\\envs\\cv2\\lib\\site-packages\\pydantic\\_internal\\_generate_schema.py\", line 2185, in <lambda>\n",
      "    lambda source, handler: handler(source)\n",
      "  File \"c:\\anaconda3\\envs\\cv2\\lib\\site-packages\\pydantic\\_internal\\_schema_generation_shared.py\", line 83, in __call__\n",
      "    schema = self._handler(source_type)\n",
      "  File \"c:\\anaconda3\\envs\\cv2\\lib\\site-packages\\pydantic\\_internal\\_generate_schema.py\", line 2088, in inner_handler\n",
      "    schema = self._generate_schema_inner(obj)\n",
      "  File \"c:\\anaconda3\\envs\\cv2\\lib\\site-packages\\pydantic\\_internal\\_generate_schema.py\", line 929, in _generate_schema_inner\n",
      "    return self.match_type(obj)\n",
      "  File \"c:\\anaconda3\\envs\\cv2\\lib\\site-packages\\pydantic\\_internal\\_generate_schema.py\", line 1029, in match_type\n",
      "    return self._match_generic_type(obj, origin)\n",
      "  File \"c:\\anaconda3\\envs\\cv2\\lib\\site-packages\\pydantic\\_internal\\_generate_schema.py\", line 1058, in _match_generic_type\n",
      "    return self._union_schema(obj)\n",
      "  File \"c:\\anaconda3\\envs\\cv2\\lib\\site-packages\\pydantic\\_internal\\_generate_schema.py\", line 1378, in _union_schema\n",
      "    choices.append(self.generate_schema(arg))\n",
      "  File \"c:\\anaconda3\\envs\\cv2\\lib\\site-packages\\pydantic\\_internal\\_generate_schema.py\", line 655, in generate_schema\n",
      "    schema = self._generate_schema_inner(obj)\n",
      "  File \"c:\\anaconda3\\envs\\cv2\\lib\\site-packages\\pydantic\\_internal\\_generate_schema.py\", line 929, in _generate_schema_inner\n",
      "    return self.match_type(obj)\n",
      "  File \"c:\\anaconda3\\envs\\cv2\\lib\\site-packages\\pydantic\\_internal\\_generate_schema.py\", line 1038, in match_type\n",
      "    return self._unknown_type_schema(obj)\n",
      "  File \"c:\\anaconda3\\envs\\cv2\\lib\\site-packages\\pydantic\\_internal\\_generate_schema.py\", line 558, in _unknown_type_schema\n",
      "    raise PydanticSchemaGenerationError(\n",
      "pydantic.errors.PydanticSchemaGenerationError: Unable to generate pydantic-core schema for <class 'starlette.requests.Request'>. Set `arbitrary_types_allowed=True` in the model_config to ignore this error or implement `__get_pydantic_core_schema__` on your type to fully support it.\n",
      "\n",
      "If you got this error by calling handler(<some type>) within `__get_pydantic_core_schema__` then you likely need to call `handler.generate_schema(<some type>)` since we do not call `__get_pydantic_core_schema__` on `<some type>` otherwise to avoid infinite recursion.\n",
      "\n",
      "For further information visit https://errors.pydantic.dev/2.9/u/schema-for-unknown-type\n",
      "ERROR:    Exception in ASGI application\n",
      "Traceback (most recent call last):\n",
      "  File \"c:\\anaconda3\\envs\\cv2\\lib\\site-packages\\pydantic\\type_adapter.py\", line 270, in _init_core_attrs\n",
      "    self._core_schema = _getattr_no_parents(self._type, '__pydantic_core_schema__')\n",
      "  File \"c:\\anaconda3\\envs\\cv2\\lib\\site-packages\\pydantic\\type_adapter.py\", line 112, in _getattr_no_parents\n",
      "    raise AttributeError(attribute)\n",
      "AttributeError: __pydantic_core_schema__\n",
      "\n",
      "During handling of the above exception, another exception occurred:\n",
      "\n",
      "Traceback (most recent call last):\n",
      "  File \"C:\\Users\\shjung\\AppData\\Roaming\\Python\\Python38\\site-packages\\uvicorn\\protocols\\http\\h11_impl.py\", line 406, in run_asgi\n",
      "    result = await app(  # type: ignore[func-returns-value]\n",
      "  File \"C:\\Users\\shjung\\AppData\\Roaming\\Python\\Python38\\site-packages\\uvicorn\\middleware\\proxy_headers.py\", line 70, in __call__\n",
      "    return await self.app(scope, receive, send)\n",
      "  File \"C:\\Users\\shjung\\AppData\\Roaming\\Python\\Python38\\site-packages\\fastapi\\applications.py\", line 1054, in __call__\n",
      "    await super().__call__(scope, receive, send)\n",
      "  File \"C:\\Users\\shjung\\AppData\\Roaming\\Python\\Python38\\site-packages\\starlette\\applications.py\", line 113, in __call__\n",
      "    await self.middleware_stack(scope, receive, send)\n",
      "  File \"C:\\Users\\shjung\\AppData\\Roaming\\Python\\Python38\\site-packages\\starlette\\middleware\\errors.py\", line 187, in __call__\n",
      "    raise exc\n",
      "  File \"C:\\Users\\shjung\\AppData\\Roaming\\Python\\Python38\\site-packages\\starlette\\middleware\\errors.py\", line 165, in __call__\n",
      "    await self.app(scope, receive, _send)\n",
      "  File \"C:\\Users\\shjung\\AppData\\Roaming\\Python\\Python38\\site-packages\\starlette\\middleware\\cors.py\", line 93, in __call__\n",
      "    await self.simple_response(scope, receive, send, request_headers=headers)\n",
      "  File \"C:\\Users\\shjung\\AppData\\Roaming\\Python\\Python38\\site-packages\\starlette\\middleware\\cors.py\", line 144, in simple_response\n",
      "    await self.app(scope, receive, send)\n",
      "  File \"C:\\Users\\shjung\\AppData\\Roaming\\Python\\Python38\\site-packages\\starlette\\middleware\\exceptions.py\", line 62, in __call__\n",
      "    await wrap_app_handling_exceptions(self.app, conn)(scope, receive, send)\n",
      "  File \"C:\\Users\\shjung\\AppData\\Roaming\\Python\\Python38\\site-packages\\starlette\\_exception_handler.py\", line 62, in wrapped_app\n",
      "    raise exc\n",
      "  File \"C:\\Users\\shjung\\AppData\\Roaming\\Python\\Python38\\site-packages\\starlette\\_exception_handler.py\", line 51, in wrapped_app\n",
      "    await app(scope, receive, sender)\n",
      "  File \"C:\\Users\\shjung\\AppData\\Roaming\\Python\\Python38\\site-packages\\starlette\\routing.py\", line 715, in __call__\n",
      "    await self.middleware_stack(scope, receive, send)\n",
      "  File \"C:\\Users\\shjung\\AppData\\Roaming\\Python\\Python38\\site-packages\\starlette\\routing.py\", line 735, in app\n",
      "    await route.handle(scope, receive, send)\n",
      "  File \"C:\\Users\\shjung\\AppData\\Roaming\\Python\\Python38\\site-packages\\starlette\\routing.py\", line 288, in handle\n",
      "    await self.app(scope, receive, send)\n",
      "  File \"C:\\Users\\shjung\\AppData\\Roaming\\Python\\Python38\\site-packages\\starlette\\routing.py\", line 76, in app\n",
      "    await wrap_app_handling_exceptions(app, request)(scope, receive, send)\n",
      "  File \"C:\\Users\\shjung\\AppData\\Roaming\\Python\\Python38\\site-packages\\starlette\\_exception_handler.py\", line 62, in wrapped_app\n",
      "    raise exc\n",
      "  File \"C:\\Users\\shjung\\AppData\\Roaming\\Python\\Python38\\site-packages\\starlette\\_exception_handler.py\", line 51, in wrapped_app\n",
      "    await app(scope, receive, sender)\n",
      "  File \"C:\\Users\\shjung\\AppData\\Roaming\\Python\\Python38\\site-packages\\starlette\\routing.py\", line 73, in app\n",
      "    response = await f(request)\n",
      "  File \"C:\\Users\\shjung\\AppData\\Roaming\\Python\\Python38\\site-packages\\fastapi\\routing.py\", line 291, in app\n",
      "    solved_result = await solve_dependencies(\n",
      "  File \"C:\\Users\\shjung\\AppData\\Roaming\\Python\\Python38\\site-packages\\fastapi\\dependencies\\utils.py\", line 656, in solve_dependencies\n",
      "    ) = await request_body_to_args(  # body_params checked above\n",
      "  File \"C:\\Users\\shjung\\AppData\\Roaming\\Python\\Python38\\site-packages\\fastapi\\dependencies\\utils.py\", line 881, in request_body_to_args\n",
      "    fields_to_extract = get_cached_model_fields(first_field.type_)\n",
      "  File \"C:\\Users\\shjung\\AppData\\Roaming\\Python\\Python38\\site-packages\\fastapi\\_compat.py\", line 657, in get_cached_model_fields\n",
      "    return get_model_fields(model)\n",
      "  File \"C:\\Users\\shjung\\AppData\\Roaming\\Python\\Python38\\site-packages\\fastapi\\_compat.py\", line 284, in get_model_fields\n",
      "    return [\n",
      "  File \"C:\\Users\\shjung\\AppData\\Roaming\\Python\\Python38\\site-packages\\fastapi\\_compat.py\", line 285, in <listcomp>\n",
      "    ModelField(field_info=field_info, name=name)\n",
      "  File \"<string>\", line 6, in __init__\n",
      "  File \"C:\\Users\\shjung\\AppData\\Roaming\\Python\\Python38\\site-packages\\fastapi\\_compat.py\", line 110, in __post_init__\n",
      "    self._type_adapter: TypeAdapter[Any] = TypeAdapter(\n",
      "  File \"c:\\anaconda3\\envs\\cv2\\lib\\site-packages\\pydantic\\type_adapter.py\", line 257, in __init__\n",
      "    self._init_core_attrs(rebuild_mocks=False)\n",
      "  File \"c:\\anaconda3\\envs\\cv2\\lib\\site-packages\\pydantic\\type_adapter.py\", line 135, in wrapped\n",
      "    return func(self, *args, **kwargs)\n",
      "  File \"c:\\anaconda3\\envs\\cv2\\lib\\site-packages\\pydantic\\type_adapter.py\", line 277, in _init_core_attrs\n",
      "    self._core_schema = _get_schema(self._type, config_wrapper, parent_depth=self._parent_depth)\n",
      "  File \"c:\\anaconda3\\envs\\cv2\\lib\\site-packages\\pydantic\\type_adapter.py\", line 95, in _get_schema\n",
      "    schema = gen.generate_schema(type_)\n",
      "  File \"c:\\anaconda3\\envs\\cv2\\lib\\site-packages\\pydantic\\_internal\\_generate_schema.py\", line 655, in generate_schema\n",
      "    schema = self._generate_schema_inner(obj)\n",
      "  File \"c:\\anaconda3\\envs\\cv2\\lib\\site-packages\\pydantic\\_internal\\_generate_schema.py\", line 908, in _generate_schema_inner\n",
      "    return self._annotated_schema(obj)\n",
      "  File \"c:\\anaconda3\\envs\\cv2\\lib\\site-packages\\pydantic\\_internal\\_generate_schema.py\", line 2028, in _annotated_schema\n",
      "    schema = self._apply_annotations(source_type, annotations)\n",
      "  File \"c:\\anaconda3\\envs\\cv2\\lib\\site-packages\\pydantic\\_internal\\_generate_schema.py\", line 2107, in _apply_annotations\n",
      "    schema = get_inner_schema(source_type)\n",
      "  File \"c:\\anaconda3\\envs\\cv2\\lib\\site-packages\\pydantic\\_internal\\_schema_generation_shared.py\", line 83, in __call__\n",
      "    schema = self._handler(source_type)\n",
      "  File \"c:\\anaconda3\\envs\\cv2\\lib\\site-packages\\pydantic\\_internal\\_generate_schema.py\", line 2189, in new_handler\n",
      "    schema = metadata_get_schema(source, get_inner_schema)\n",
      "  File \"c:\\anaconda3\\envs\\cv2\\lib\\site-packages\\pydantic\\_internal\\_generate_schema.py\", line 2185, in <lambda>\n",
      "    lambda source, handler: handler(source)\n",
      "  File \"c:\\anaconda3\\envs\\cv2\\lib\\site-packages\\pydantic\\_internal\\_schema_generation_shared.py\", line 83, in __call__\n",
      "    schema = self._handler(source_type)\n",
      "  File \"c:\\anaconda3\\envs\\cv2\\lib\\site-packages\\pydantic\\_internal\\_generate_schema.py\", line 2088, in inner_handler\n",
      "    schema = self._generate_schema_inner(obj)\n",
      "  File \"c:\\anaconda3\\envs\\cv2\\lib\\site-packages\\pydantic\\_internal\\_generate_schema.py\", line 929, in _generate_schema_inner\n",
      "    return self.match_type(obj)\n",
      "  File \"c:\\anaconda3\\envs\\cv2\\lib\\site-packages\\pydantic\\_internal\\_generate_schema.py\", line 1029, in match_type\n",
      "    return self._match_generic_type(obj, origin)\n",
      "  File \"c:\\anaconda3\\envs\\cv2\\lib\\site-packages\\pydantic\\_internal\\_generate_schema.py\", line 1058, in _match_generic_type\n",
      "    return self._union_schema(obj)\n",
      "  File \"c:\\anaconda3\\envs\\cv2\\lib\\site-packages\\pydantic\\_internal\\_generate_schema.py\", line 1378, in _union_schema\n",
      "    choices.append(self.generate_schema(arg))\n",
      "  File \"c:\\anaconda3\\envs\\cv2\\lib\\site-packages\\pydantic\\_internal\\_generate_schema.py\", line 655, in generate_schema\n",
      "    schema = self._generate_schema_inner(obj)\n",
      "  File \"c:\\anaconda3\\envs\\cv2\\lib\\site-packages\\pydantic\\_internal\\_generate_schema.py\", line 929, in _generate_schema_inner\n",
      "    return self.match_type(obj)\n",
      "  File \"c:\\anaconda3\\envs\\cv2\\lib\\site-packages\\pydantic\\_internal\\_generate_schema.py\", line 1038, in match_type\n",
      "    return self._unknown_type_schema(obj)\n",
      "  File \"c:\\anaconda3\\envs\\cv2\\lib\\site-packages\\pydantic\\_internal\\_generate_schema.py\", line 558, in _unknown_type_schema\n",
      "    raise PydanticSchemaGenerationError(\n",
      "pydantic.errors.PydanticSchemaGenerationError: Unable to generate pydantic-core schema for <class 'starlette.requests.Request'>. Set `arbitrary_types_allowed=True` in the model_config to ignore this error or implement `__get_pydantic_core_schema__` on your type to fully support it.\n",
      "\n",
      "If you got this error by calling handler(<some type>) within `__get_pydantic_core_schema__` then you likely need to call `handler.generate_schema(<some type>)` since we do not call `__get_pydantic_core_schema__` on `<some type>` otherwise to avoid infinite recursion.\n",
      "\n",
      "For further information visit https://errors.pydantic.dev/2.9/u/schema-for-unknown-type\n",
      "ERROR:    Exception in ASGI application\n",
      "Traceback (most recent call last):\n",
      "  File \"c:\\anaconda3\\envs\\cv2\\lib\\site-packages\\pydantic\\type_adapter.py\", line 270, in _init_core_attrs\n",
      "    self._core_schema = _getattr_no_parents(self._type, '__pydantic_core_schema__')\n",
      "  File \"c:\\anaconda3\\envs\\cv2\\lib\\site-packages\\pydantic\\type_adapter.py\", line 112, in _getattr_no_parents\n",
      "    raise AttributeError(attribute)\n",
      "AttributeError: __pydantic_core_schema__\n",
      "\n",
      "During handling of the above exception, another exception occurred:\n",
      "\n",
      "Traceback (most recent call last):\n",
      "  File \"C:\\Users\\shjung\\AppData\\Roaming\\Python\\Python38\\site-packages\\uvicorn\\protocols\\http\\h11_impl.py\", line 406, in run_asgi\n",
      "    result = await app(  # type: ignore[func-returns-value]\n",
      "  File \"C:\\Users\\shjung\\AppData\\Roaming\\Python\\Python38\\site-packages\\uvicorn\\middleware\\proxy_headers.py\", line 70, in __call__\n",
      "    return await self.app(scope, receive, send)\n",
      "  File \"C:\\Users\\shjung\\AppData\\Roaming\\Python\\Python38\\site-packages\\fastapi\\applications.py\", line 1054, in __call__\n",
      "    await super().__call__(scope, receive, send)\n",
      "  File \"C:\\Users\\shjung\\AppData\\Roaming\\Python\\Python38\\site-packages\\starlette\\applications.py\", line 113, in __call__\n",
      "    await self.middleware_stack(scope, receive, send)\n",
      "  File \"C:\\Users\\shjung\\AppData\\Roaming\\Python\\Python38\\site-packages\\starlette\\middleware\\errors.py\", line 187, in __call__\n",
      "    raise exc\n",
      "  File \"C:\\Users\\shjung\\AppData\\Roaming\\Python\\Python38\\site-packages\\starlette\\middleware\\errors.py\", line 165, in __call__\n",
      "    await self.app(scope, receive, _send)\n",
      "  File \"C:\\Users\\shjung\\AppData\\Roaming\\Python\\Python38\\site-packages\\starlette\\middleware\\cors.py\", line 93, in __call__\n",
      "    await self.simple_response(scope, receive, send, request_headers=headers)\n",
      "  File \"C:\\Users\\shjung\\AppData\\Roaming\\Python\\Python38\\site-packages\\starlette\\middleware\\cors.py\", line 144, in simple_response\n",
      "    await self.app(scope, receive, send)\n",
      "  File \"C:\\Users\\shjung\\AppData\\Roaming\\Python\\Python38\\site-packages\\starlette\\middleware\\exceptions.py\", line 62, in __call__\n",
      "    await wrap_app_handling_exceptions(self.app, conn)(scope, receive, send)\n",
      "  File \"C:\\Users\\shjung\\AppData\\Roaming\\Python\\Python38\\site-packages\\starlette\\_exception_handler.py\", line 62, in wrapped_app\n",
      "    raise exc\n",
      "  File \"C:\\Users\\shjung\\AppData\\Roaming\\Python\\Python38\\site-packages\\starlette\\_exception_handler.py\", line 51, in wrapped_app\n",
      "    await app(scope, receive, sender)\n",
      "  File \"C:\\Users\\shjung\\AppData\\Roaming\\Python\\Python38\\site-packages\\starlette\\routing.py\", line 715, in __call__\n",
      "    await self.middleware_stack(scope, receive, send)\n",
      "  File \"C:\\Users\\shjung\\AppData\\Roaming\\Python\\Python38\\site-packages\\starlette\\routing.py\", line 735, in app\n",
      "    await route.handle(scope, receive, send)\n",
      "  File \"C:\\Users\\shjung\\AppData\\Roaming\\Python\\Python38\\site-packages\\starlette\\routing.py\", line 288, in handle\n",
      "    await self.app(scope, receive, send)\n",
      "  File \"C:\\Users\\shjung\\AppData\\Roaming\\Python\\Python38\\site-packages\\starlette\\routing.py\", line 76, in app\n",
      "    await wrap_app_handling_exceptions(app, request)(scope, receive, send)\n",
      "  File \"C:\\Users\\shjung\\AppData\\Roaming\\Python\\Python38\\site-packages\\starlette\\_exception_handler.py\", line 62, in wrapped_app\n",
      "    raise exc\n",
      "  File \"C:\\Users\\shjung\\AppData\\Roaming\\Python\\Python38\\site-packages\\starlette\\_exception_handler.py\", line 51, in wrapped_app\n",
      "    await app(scope, receive, sender)\n",
      "  File \"C:\\Users\\shjung\\AppData\\Roaming\\Python\\Python38\\site-packages\\starlette\\routing.py\", line 73, in app\n",
      "    response = await f(request)\n",
      "  File \"C:\\Users\\shjung\\AppData\\Roaming\\Python\\Python38\\site-packages\\fastapi\\routing.py\", line 291, in app\n",
      "    solved_result = await solve_dependencies(\n",
      "  File \"C:\\Users\\shjung\\AppData\\Roaming\\Python\\Python38\\site-packages\\fastapi\\dependencies\\utils.py\", line 656, in solve_dependencies\n",
      "    ) = await request_body_to_args(  # body_params checked above\n",
      "  File \"C:\\Users\\shjung\\AppData\\Roaming\\Python\\Python38\\site-packages\\fastapi\\dependencies\\utils.py\", line 881, in request_body_to_args\n",
      "    fields_to_extract = get_cached_model_fields(first_field.type_)\n",
      "  File \"C:\\Users\\shjung\\AppData\\Roaming\\Python\\Python38\\site-packages\\fastapi\\_compat.py\", line 657, in get_cached_model_fields\n",
      "    return get_model_fields(model)\n",
      "  File \"C:\\Users\\shjung\\AppData\\Roaming\\Python\\Python38\\site-packages\\fastapi\\_compat.py\", line 284, in get_model_fields\n",
      "    return [\n",
      "  File \"C:\\Users\\shjung\\AppData\\Roaming\\Python\\Python38\\site-packages\\fastapi\\_compat.py\", line 285, in <listcomp>\n",
      "    ModelField(field_info=field_info, name=name)\n",
      "  File \"<string>\", line 6, in __init__\n",
      "  File \"C:\\Users\\shjung\\AppData\\Roaming\\Python\\Python38\\site-packages\\fastapi\\_compat.py\", line 110, in __post_init__\n",
      "    self._type_adapter: TypeAdapter[Any] = TypeAdapter(\n",
      "  File \"c:\\anaconda3\\envs\\cv2\\lib\\site-packages\\pydantic\\type_adapter.py\", line 257, in __init__\n",
      "    self._init_core_attrs(rebuild_mocks=False)\n",
      "  File \"c:\\anaconda3\\envs\\cv2\\lib\\site-packages\\pydantic\\type_adapter.py\", line 135, in wrapped\n",
      "    return func(self, *args, **kwargs)\n",
      "  File \"c:\\anaconda3\\envs\\cv2\\lib\\site-packages\\pydantic\\type_adapter.py\", line 277, in _init_core_attrs\n",
      "    self._core_schema = _get_schema(self._type, config_wrapper, parent_depth=self._parent_depth)\n",
      "  File \"c:\\anaconda3\\envs\\cv2\\lib\\site-packages\\pydantic\\type_adapter.py\", line 95, in _get_schema\n",
      "    schema = gen.generate_schema(type_)\n",
      "  File \"c:\\anaconda3\\envs\\cv2\\lib\\site-packages\\pydantic\\_internal\\_generate_schema.py\", line 655, in generate_schema\n",
      "    schema = self._generate_schema_inner(obj)\n",
      "  File \"c:\\anaconda3\\envs\\cv2\\lib\\site-packages\\pydantic\\_internal\\_generate_schema.py\", line 908, in _generate_schema_inner\n",
      "    return self._annotated_schema(obj)\n",
      "  File \"c:\\anaconda3\\envs\\cv2\\lib\\site-packages\\pydantic\\_internal\\_generate_schema.py\", line 2028, in _annotated_schema\n",
      "    schema = self._apply_annotations(source_type, annotations)\n",
      "  File \"c:\\anaconda3\\envs\\cv2\\lib\\site-packages\\pydantic\\_internal\\_generate_schema.py\", line 2107, in _apply_annotations\n",
      "    schema = get_inner_schema(source_type)\n",
      "  File \"c:\\anaconda3\\envs\\cv2\\lib\\site-packages\\pydantic\\_internal\\_schema_generation_shared.py\", line 83, in __call__\n",
      "    schema = self._handler(source_type)\n",
      "  File \"c:\\anaconda3\\envs\\cv2\\lib\\site-packages\\pydantic\\_internal\\_generate_schema.py\", line 2189, in new_handler\n",
      "    schema = metadata_get_schema(source, get_inner_schema)\n",
      "  File \"c:\\anaconda3\\envs\\cv2\\lib\\site-packages\\pydantic\\_internal\\_generate_schema.py\", line 2185, in <lambda>\n",
      "    lambda source, handler: handler(source)\n",
      "  File \"c:\\anaconda3\\envs\\cv2\\lib\\site-packages\\pydantic\\_internal\\_schema_generation_shared.py\", line 83, in __call__\n",
      "    schema = self._handler(source_type)\n",
      "  File \"c:\\anaconda3\\envs\\cv2\\lib\\site-packages\\pydantic\\_internal\\_generate_schema.py\", line 2088, in inner_handler\n",
      "    schema = self._generate_schema_inner(obj)\n",
      "  File \"c:\\anaconda3\\envs\\cv2\\lib\\site-packages\\pydantic\\_internal\\_generate_schema.py\", line 929, in _generate_schema_inner\n",
      "    return self.match_type(obj)\n",
      "  File \"c:\\anaconda3\\envs\\cv2\\lib\\site-packages\\pydantic\\_internal\\_generate_schema.py\", line 1029, in match_type\n",
      "    return self._match_generic_type(obj, origin)\n",
      "  File \"c:\\anaconda3\\envs\\cv2\\lib\\site-packages\\pydantic\\_internal\\_generate_schema.py\", line 1058, in _match_generic_type\n",
      "    return self._union_schema(obj)\n",
      "  File \"c:\\anaconda3\\envs\\cv2\\lib\\site-packages\\pydantic\\_internal\\_generate_schema.py\", line 1378, in _union_schema\n",
      "    choices.append(self.generate_schema(arg))\n",
      "  File \"c:\\anaconda3\\envs\\cv2\\lib\\site-packages\\pydantic\\_internal\\_generate_schema.py\", line 655, in generate_schema\n",
      "    schema = self._generate_schema_inner(obj)\n",
      "  File \"c:\\anaconda3\\envs\\cv2\\lib\\site-packages\\pydantic\\_internal\\_generate_schema.py\", line 929, in _generate_schema_inner\n",
      "    return self.match_type(obj)\n",
      "  File \"c:\\anaconda3\\envs\\cv2\\lib\\site-packages\\pydantic\\_internal\\_generate_schema.py\", line 1038, in match_type\n",
      "    return self._unknown_type_schema(obj)\n",
      "  File \"c:\\anaconda3\\envs\\cv2\\lib\\site-packages\\pydantic\\_internal\\_generate_schema.py\", line 558, in _unknown_type_schema\n",
      "    raise PydanticSchemaGenerationError(\n",
      "pydantic.errors.PydanticSchemaGenerationError: Unable to generate pydantic-core schema for <class 'starlette.requests.Request'>. Set `arbitrary_types_allowed=True` in the model_config to ignore this error or implement `__get_pydantic_core_schema__` on your type to fully support it.\n",
      "\n",
      "If you got this error by calling handler(<some type>) within `__get_pydantic_core_schema__` then you likely need to call `handler.generate_schema(<some type>)` since we do not call `__get_pydantic_core_schema__` on `<some type>` otherwise to avoid infinite recursion.\n",
      "\n",
      "For further information visit https://errors.pydantic.dev/2.9/u/schema-for-unknown-type\n",
      "ERROR:    Exception in ASGI application\n",
      "Traceback (most recent call last):\n",
      "  File \"c:\\anaconda3\\envs\\cv2\\lib\\site-packages\\pydantic\\type_adapter.py\", line 270, in _init_core_attrs\n",
      "    self._core_schema = _getattr_no_parents(self._type, '__pydantic_core_schema__')\n",
      "  File \"c:\\anaconda3\\envs\\cv2\\lib\\site-packages\\pydantic\\type_adapter.py\", line 112, in _getattr_no_parents\n",
      "    raise AttributeError(attribute)\n",
      "AttributeError: __pydantic_core_schema__\n",
      "\n",
      "During handling of the above exception, another exception occurred:\n",
      "\n",
      "Traceback (most recent call last):\n",
      "  File \"C:\\Users\\shjung\\AppData\\Roaming\\Python\\Python38\\site-packages\\uvicorn\\protocols\\http\\h11_impl.py\", line 406, in run_asgi\n",
      "    result = await app(  # type: ignore[func-returns-value]\n",
      "  File \"C:\\Users\\shjung\\AppData\\Roaming\\Python\\Python38\\site-packages\\uvicorn\\middleware\\proxy_headers.py\", line 70, in __call__\n",
      "    return await self.app(scope, receive, send)\n",
      "  File \"C:\\Users\\shjung\\AppData\\Roaming\\Python\\Python38\\site-packages\\fastapi\\applications.py\", line 1054, in __call__\n",
      "    await super().__call__(scope, receive, send)\n",
      "  File \"C:\\Users\\shjung\\AppData\\Roaming\\Python\\Python38\\site-packages\\starlette\\applications.py\", line 113, in __call__\n",
      "    await self.middleware_stack(scope, receive, send)\n",
      "  File \"C:\\Users\\shjung\\AppData\\Roaming\\Python\\Python38\\site-packages\\starlette\\middleware\\errors.py\", line 187, in __call__\n",
      "    raise exc\n",
      "  File \"C:\\Users\\shjung\\AppData\\Roaming\\Python\\Python38\\site-packages\\starlette\\middleware\\errors.py\", line 165, in __call__\n",
      "    await self.app(scope, receive, _send)\n",
      "  File \"C:\\Users\\shjung\\AppData\\Roaming\\Python\\Python38\\site-packages\\starlette\\middleware\\cors.py\", line 93, in __call__\n",
      "    await self.simple_response(scope, receive, send, request_headers=headers)\n",
      "  File \"C:\\Users\\shjung\\AppData\\Roaming\\Python\\Python38\\site-packages\\starlette\\middleware\\cors.py\", line 144, in simple_response\n",
      "    await self.app(scope, receive, send)\n",
      "  File \"C:\\Users\\shjung\\AppData\\Roaming\\Python\\Python38\\site-packages\\starlette\\middleware\\exceptions.py\", line 62, in __call__\n",
      "    await wrap_app_handling_exceptions(self.app, conn)(scope, receive, send)\n",
      "  File \"C:\\Users\\shjung\\AppData\\Roaming\\Python\\Python38\\site-packages\\starlette\\_exception_handler.py\", line 62, in wrapped_app\n",
      "    raise exc\n",
      "  File \"C:\\Users\\shjung\\AppData\\Roaming\\Python\\Python38\\site-packages\\starlette\\_exception_handler.py\", line 51, in wrapped_app\n",
      "    await app(scope, receive, sender)\n",
      "  File \"C:\\Users\\shjung\\AppData\\Roaming\\Python\\Python38\\site-packages\\starlette\\routing.py\", line 715, in __call__\n",
      "    await self.middleware_stack(scope, receive, send)\n",
      "  File \"C:\\Users\\shjung\\AppData\\Roaming\\Python\\Python38\\site-packages\\starlette\\routing.py\", line 735, in app\n",
      "    await route.handle(scope, receive, send)\n",
      "  File \"C:\\Users\\shjung\\AppData\\Roaming\\Python\\Python38\\site-packages\\starlette\\routing.py\", line 288, in handle\n",
      "    await self.app(scope, receive, send)\n",
      "  File \"C:\\Users\\shjung\\AppData\\Roaming\\Python\\Python38\\site-packages\\starlette\\routing.py\", line 76, in app\n",
      "    await wrap_app_handling_exceptions(app, request)(scope, receive, send)\n",
      "  File \"C:\\Users\\shjung\\AppData\\Roaming\\Python\\Python38\\site-packages\\starlette\\_exception_handler.py\", line 62, in wrapped_app\n",
      "    raise exc\n",
      "  File \"C:\\Users\\shjung\\AppData\\Roaming\\Python\\Python38\\site-packages\\starlette\\_exception_handler.py\", line 51, in wrapped_app\n",
      "    await app(scope, receive, sender)\n",
      "  File \"C:\\Users\\shjung\\AppData\\Roaming\\Python\\Python38\\site-packages\\starlette\\routing.py\", line 73, in app\n",
      "    response = await f(request)\n",
      "  File \"C:\\Users\\shjung\\AppData\\Roaming\\Python\\Python38\\site-packages\\fastapi\\routing.py\", line 291, in app\n",
      "    solved_result = await solve_dependencies(\n",
      "  File \"C:\\Users\\shjung\\AppData\\Roaming\\Python\\Python38\\site-packages\\fastapi\\dependencies\\utils.py\", line 656, in solve_dependencies\n",
      "    ) = await request_body_to_args(  # body_params checked above\n",
      "  File \"C:\\Users\\shjung\\AppData\\Roaming\\Python\\Python38\\site-packages\\fastapi\\dependencies\\utils.py\", line 881, in request_body_to_args\n",
      "    fields_to_extract = get_cached_model_fields(first_field.type_)\n",
      "  File \"C:\\Users\\shjung\\AppData\\Roaming\\Python\\Python38\\site-packages\\fastapi\\_compat.py\", line 657, in get_cached_model_fields\n",
      "    return get_model_fields(model)\n",
      "  File \"C:\\Users\\shjung\\AppData\\Roaming\\Python\\Python38\\site-packages\\fastapi\\_compat.py\", line 284, in get_model_fields\n",
      "    return [\n",
      "  File \"C:\\Users\\shjung\\AppData\\Roaming\\Python\\Python38\\site-packages\\fastapi\\_compat.py\", line 285, in <listcomp>\n",
      "    ModelField(field_info=field_info, name=name)\n",
      "  File \"<string>\", line 6, in __init__\n",
      "  File \"C:\\Users\\shjung\\AppData\\Roaming\\Python\\Python38\\site-packages\\fastapi\\_compat.py\", line 110, in __post_init__\n",
      "    self._type_adapter: TypeAdapter[Any] = TypeAdapter(\n",
      "  File \"c:\\anaconda3\\envs\\cv2\\lib\\site-packages\\pydantic\\type_adapter.py\", line 257, in __init__\n",
      "    self._init_core_attrs(rebuild_mocks=False)\n",
      "  File \"c:\\anaconda3\\envs\\cv2\\lib\\site-packages\\pydantic\\type_adapter.py\", line 135, in wrapped\n",
      "    return func(self, *args, **kwargs)\n",
      "  File \"c:\\anaconda3\\envs\\cv2\\lib\\site-packages\\pydantic\\type_adapter.py\", line 277, in _init_core_attrs\n",
      "    self._core_schema = _get_schema(self._type, config_wrapper, parent_depth=self._parent_depth)\n",
      "  File \"c:\\anaconda3\\envs\\cv2\\lib\\site-packages\\pydantic\\type_adapter.py\", line 95, in _get_schema\n",
      "    schema = gen.generate_schema(type_)\n",
      "  File \"c:\\anaconda3\\envs\\cv2\\lib\\site-packages\\pydantic\\_internal\\_generate_schema.py\", line 655, in generate_schema\n",
      "    schema = self._generate_schema_inner(obj)\n",
      "  File \"c:\\anaconda3\\envs\\cv2\\lib\\site-packages\\pydantic\\_internal\\_generate_schema.py\", line 908, in _generate_schema_inner\n",
      "    return self._annotated_schema(obj)\n",
      "  File \"c:\\anaconda3\\envs\\cv2\\lib\\site-packages\\pydantic\\_internal\\_generate_schema.py\", line 2028, in _annotated_schema\n",
      "    schema = self._apply_annotations(source_type, annotations)\n",
      "  File \"c:\\anaconda3\\envs\\cv2\\lib\\site-packages\\pydantic\\_internal\\_generate_schema.py\", line 2107, in _apply_annotations\n",
      "    schema = get_inner_schema(source_type)\n",
      "  File \"c:\\anaconda3\\envs\\cv2\\lib\\site-packages\\pydantic\\_internal\\_schema_generation_shared.py\", line 83, in __call__\n",
      "    schema = self._handler(source_type)\n",
      "  File \"c:\\anaconda3\\envs\\cv2\\lib\\site-packages\\pydantic\\_internal\\_generate_schema.py\", line 2189, in new_handler\n",
      "    schema = metadata_get_schema(source, get_inner_schema)\n",
      "  File \"c:\\anaconda3\\envs\\cv2\\lib\\site-packages\\pydantic\\_internal\\_generate_schema.py\", line 2185, in <lambda>\n",
      "    lambda source, handler: handler(source)\n",
      "  File \"c:\\anaconda3\\envs\\cv2\\lib\\site-packages\\pydantic\\_internal\\_schema_generation_shared.py\", line 83, in __call__\n",
      "    schema = self._handler(source_type)\n",
      "  File \"c:\\anaconda3\\envs\\cv2\\lib\\site-packages\\pydantic\\_internal\\_generate_schema.py\", line 2088, in inner_handler\n",
      "    schema = self._generate_schema_inner(obj)\n",
      "  File \"c:\\anaconda3\\envs\\cv2\\lib\\site-packages\\pydantic\\_internal\\_generate_schema.py\", line 929, in _generate_schema_inner\n",
      "    return self.match_type(obj)\n",
      "  File \"c:\\anaconda3\\envs\\cv2\\lib\\site-packages\\pydantic\\_internal\\_generate_schema.py\", line 1029, in match_type\n",
      "    return self._match_generic_type(obj, origin)\n",
      "  File \"c:\\anaconda3\\envs\\cv2\\lib\\site-packages\\pydantic\\_internal\\_generate_schema.py\", line 1058, in _match_generic_type\n",
      "    return self._union_schema(obj)\n",
      "  File \"c:\\anaconda3\\envs\\cv2\\lib\\site-packages\\pydantic\\_internal\\_generate_schema.py\", line 1378, in _union_schema\n",
      "    choices.append(self.generate_schema(arg))\n",
      "  File \"c:\\anaconda3\\envs\\cv2\\lib\\site-packages\\pydantic\\_internal\\_generate_schema.py\", line 655, in generate_schema\n",
      "    schema = self._generate_schema_inner(obj)\n",
      "  File \"c:\\anaconda3\\envs\\cv2\\lib\\site-packages\\pydantic\\_internal\\_generate_schema.py\", line 929, in _generate_schema_inner\n",
      "    return self.match_type(obj)\n",
      "  File \"c:\\anaconda3\\envs\\cv2\\lib\\site-packages\\pydantic\\_internal\\_generate_schema.py\", line 1038, in match_type\n",
      "    return self._unknown_type_schema(obj)\n",
      "  File \"c:\\anaconda3\\envs\\cv2\\lib\\site-packages\\pydantic\\_internal\\_generate_schema.py\", line 558, in _unknown_type_schema\n",
      "    raise PydanticSchemaGenerationError(\n",
      "pydantic.errors.PydanticSchemaGenerationError: Unable to generate pydantic-core schema for <class 'starlette.requests.Request'>. Set `arbitrary_types_allowed=True` in the model_config to ignore this error or implement `__get_pydantic_core_schema__` on your type to fully support it.\n",
      "\n",
      "If you got this error by calling handler(<some type>) within `__get_pydantic_core_schema__` then you likely need to call `handler.generate_schema(<some type>)` since we do not call `__get_pydantic_core_schema__` on `<some type>` otherwise to avoid infinite recursion.\n",
      "\n",
      "For further information visit https://errors.pydantic.dev/2.9/u/schema-for-unknown-type\n",
      "ERROR:    Exception in ASGI application\n",
      "Traceback (most recent call last):\n",
      "  File \"c:\\anaconda3\\envs\\cv2\\lib\\site-packages\\pydantic\\type_adapter.py\", line 270, in _init_core_attrs\n",
      "    self._core_schema = _getattr_no_parents(self._type, '__pydantic_core_schema__')\n",
      "  File \"c:\\anaconda3\\envs\\cv2\\lib\\site-packages\\pydantic\\type_adapter.py\", line 112, in _getattr_no_parents\n",
      "    raise AttributeError(attribute)\n",
      "AttributeError: __pydantic_core_schema__\n",
      "\n",
      "During handling of the above exception, another exception occurred:\n",
      "\n",
      "Traceback (most recent call last):\n",
      "  File \"C:\\Users\\shjung\\AppData\\Roaming\\Python\\Python38\\site-packages\\uvicorn\\protocols\\http\\h11_impl.py\", line 406, in run_asgi\n",
      "    result = await app(  # type: ignore[func-returns-value]\n",
      "  File \"C:\\Users\\shjung\\AppData\\Roaming\\Python\\Python38\\site-packages\\uvicorn\\middleware\\proxy_headers.py\", line 70, in __call__\n",
      "    return await self.app(scope, receive, send)\n",
      "  File \"C:\\Users\\shjung\\AppData\\Roaming\\Python\\Python38\\site-packages\\fastapi\\applications.py\", line 1054, in __call__\n",
      "    await super().__call__(scope, receive, send)\n",
      "  File \"C:\\Users\\shjung\\AppData\\Roaming\\Python\\Python38\\site-packages\\starlette\\applications.py\", line 113, in __call__\n",
      "    await self.middleware_stack(scope, receive, send)\n",
      "  File \"C:\\Users\\shjung\\AppData\\Roaming\\Python\\Python38\\site-packages\\starlette\\middleware\\errors.py\", line 187, in __call__\n",
      "    raise exc\n",
      "  File \"C:\\Users\\shjung\\AppData\\Roaming\\Python\\Python38\\site-packages\\starlette\\middleware\\errors.py\", line 165, in __call__\n",
      "    await self.app(scope, receive, _send)\n",
      "  File \"C:\\Users\\shjung\\AppData\\Roaming\\Python\\Python38\\site-packages\\starlette\\middleware\\cors.py\", line 93, in __call__\n",
      "    await self.simple_response(scope, receive, send, request_headers=headers)\n",
      "  File \"C:\\Users\\shjung\\AppData\\Roaming\\Python\\Python38\\site-packages\\starlette\\middleware\\cors.py\", line 144, in simple_response\n",
      "    await self.app(scope, receive, send)\n",
      "  File \"C:\\Users\\shjung\\AppData\\Roaming\\Python\\Python38\\site-packages\\starlette\\middleware\\exceptions.py\", line 62, in __call__\n",
      "    await wrap_app_handling_exceptions(self.app, conn)(scope, receive, send)\n",
      "  File \"C:\\Users\\shjung\\AppData\\Roaming\\Python\\Python38\\site-packages\\starlette\\_exception_handler.py\", line 62, in wrapped_app\n",
      "    raise exc\n",
      "  File \"C:\\Users\\shjung\\AppData\\Roaming\\Python\\Python38\\site-packages\\starlette\\_exception_handler.py\", line 51, in wrapped_app\n",
      "    await app(scope, receive, sender)\n",
      "  File \"C:\\Users\\shjung\\AppData\\Roaming\\Python\\Python38\\site-packages\\starlette\\routing.py\", line 715, in __call__\n",
      "    await self.middleware_stack(scope, receive, send)\n",
      "  File \"C:\\Users\\shjung\\AppData\\Roaming\\Python\\Python38\\site-packages\\starlette\\routing.py\", line 735, in app\n",
      "    await route.handle(scope, receive, send)\n",
      "  File \"C:\\Users\\shjung\\AppData\\Roaming\\Python\\Python38\\site-packages\\starlette\\routing.py\", line 288, in handle\n",
      "    await self.app(scope, receive, send)\n",
      "  File \"C:\\Users\\shjung\\AppData\\Roaming\\Python\\Python38\\site-packages\\starlette\\routing.py\", line 76, in app\n",
      "    await wrap_app_handling_exceptions(app, request)(scope, receive, send)\n",
      "  File \"C:\\Users\\shjung\\AppData\\Roaming\\Python\\Python38\\site-packages\\starlette\\_exception_handler.py\", line 62, in wrapped_app\n",
      "    raise exc\n",
      "  File \"C:\\Users\\shjung\\AppData\\Roaming\\Python\\Python38\\site-packages\\starlette\\_exception_handler.py\", line 51, in wrapped_app\n",
      "    await app(scope, receive, sender)\n",
      "  File \"C:\\Users\\shjung\\AppData\\Roaming\\Python\\Python38\\site-packages\\starlette\\routing.py\", line 73, in app\n",
      "    response = await f(request)\n",
      "  File \"C:\\Users\\shjung\\AppData\\Roaming\\Python\\Python38\\site-packages\\fastapi\\routing.py\", line 291, in app\n",
      "    solved_result = await solve_dependencies(\n",
      "  File \"C:\\Users\\shjung\\AppData\\Roaming\\Python\\Python38\\site-packages\\fastapi\\dependencies\\utils.py\", line 656, in solve_dependencies\n",
      "    ) = await request_body_to_args(  # body_params checked above\n",
      "  File \"C:\\Users\\shjung\\AppData\\Roaming\\Python\\Python38\\site-packages\\fastapi\\dependencies\\utils.py\", line 881, in request_body_to_args\n",
      "    fields_to_extract = get_cached_model_fields(first_field.type_)\n",
      "  File \"C:\\Users\\shjung\\AppData\\Roaming\\Python\\Python38\\site-packages\\fastapi\\_compat.py\", line 657, in get_cached_model_fields\n",
      "    return get_model_fields(model)\n",
      "  File \"C:\\Users\\shjung\\AppData\\Roaming\\Python\\Python38\\site-packages\\fastapi\\_compat.py\", line 284, in get_model_fields\n",
      "    return [\n",
      "  File \"C:\\Users\\shjung\\AppData\\Roaming\\Python\\Python38\\site-packages\\fastapi\\_compat.py\", line 285, in <listcomp>\n",
      "    ModelField(field_info=field_info, name=name)\n",
      "  File \"<string>\", line 6, in __init__\n",
      "  File \"C:\\Users\\shjung\\AppData\\Roaming\\Python\\Python38\\site-packages\\fastapi\\_compat.py\", line 110, in __post_init__\n",
      "    self._type_adapter: TypeAdapter[Any] = TypeAdapter(\n",
      "  File \"c:\\anaconda3\\envs\\cv2\\lib\\site-packages\\pydantic\\type_adapter.py\", line 257, in __init__\n",
      "    self._init_core_attrs(rebuild_mocks=False)\n",
      "  File \"c:\\anaconda3\\envs\\cv2\\lib\\site-packages\\pydantic\\type_adapter.py\", line 135, in wrapped\n",
      "    return func(self, *args, **kwargs)\n",
      "  File \"c:\\anaconda3\\envs\\cv2\\lib\\site-packages\\pydantic\\type_adapter.py\", line 277, in _init_core_attrs\n",
      "    self._core_schema = _get_schema(self._type, config_wrapper, parent_depth=self._parent_depth)\n",
      "  File \"c:\\anaconda3\\envs\\cv2\\lib\\site-packages\\pydantic\\type_adapter.py\", line 95, in _get_schema\n",
      "    schema = gen.generate_schema(type_)\n",
      "  File \"c:\\anaconda3\\envs\\cv2\\lib\\site-packages\\pydantic\\_internal\\_generate_schema.py\", line 655, in generate_schema\n",
      "    schema = self._generate_schema_inner(obj)\n",
      "  File \"c:\\anaconda3\\envs\\cv2\\lib\\site-packages\\pydantic\\_internal\\_generate_schema.py\", line 908, in _generate_schema_inner\n",
      "    return self._annotated_schema(obj)\n",
      "  File \"c:\\anaconda3\\envs\\cv2\\lib\\site-packages\\pydantic\\_internal\\_generate_schema.py\", line 2028, in _annotated_schema\n",
      "    schema = self._apply_annotations(source_type, annotations)\n",
      "  File \"c:\\anaconda3\\envs\\cv2\\lib\\site-packages\\pydantic\\_internal\\_generate_schema.py\", line 2107, in _apply_annotations\n",
      "    schema = get_inner_schema(source_type)\n",
      "  File \"c:\\anaconda3\\envs\\cv2\\lib\\site-packages\\pydantic\\_internal\\_schema_generation_shared.py\", line 83, in __call__\n",
      "    schema = self._handler(source_type)\n",
      "  File \"c:\\anaconda3\\envs\\cv2\\lib\\site-packages\\pydantic\\_internal\\_generate_schema.py\", line 2189, in new_handler\n",
      "    schema = metadata_get_schema(source, get_inner_schema)\n",
      "  File \"c:\\anaconda3\\envs\\cv2\\lib\\site-packages\\pydantic\\_internal\\_generate_schema.py\", line 2185, in <lambda>\n",
      "    lambda source, handler: handler(source)\n",
      "  File \"c:\\anaconda3\\envs\\cv2\\lib\\site-packages\\pydantic\\_internal\\_schema_generation_shared.py\", line 83, in __call__\n",
      "    schema = self._handler(source_type)\n",
      "  File \"c:\\anaconda3\\envs\\cv2\\lib\\site-packages\\pydantic\\_internal\\_generate_schema.py\", line 2088, in inner_handler\n",
      "    schema = self._generate_schema_inner(obj)\n",
      "  File \"c:\\anaconda3\\envs\\cv2\\lib\\site-packages\\pydantic\\_internal\\_generate_schema.py\", line 929, in _generate_schema_inner\n",
      "    return self.match_type(obj)\n",
      "  File \"c:\\anaconda3\\envs\\cv2\\lib\\site-packages\\pydantic\\_internal\\_generate_schema.py\", line 1029, in match_type\n",
      "    return self._match_generic_type(obj, origin)\n",
      "  File \"c:\\anaconda3\\envs\\cv2\\lib\\site-packages\\pydantic\\_internal\\_generate_schema.py\", line 1058, in _match_generic_type\n",
      "    return self._union_schema(obj)\n",
      "  File \"c:\\anaconda3\\envs\\cv2\\lib\\site-packages\\pydantic\\_internal\\_generate_schema.py\", line 1378, in _union_schema\n",
      "    choices.append(self.generate_schema(arg))\n",
      "  File \"c:\\anaconda3\\envs\\cv2\\lib\\site-packages\\pydantic\\_internal\\_generate_schema.py\", line 655, in generate_schema\n",
      "    schema = self._generate_schema_inner(obj)\n",
      "  File \"c:\\anaconda3\\envs\\cv2\\lib\\site-packages\\pydantic\\_internal\\_generate_schema.py\", line 929, in _generate_schema_inner\n",
      "    return self.match_type(obj)\n",
      "  File \"c:\\anaconda3\\envs\\cv2\\lib\\site-packages\\pydantic\\_internal\\_generate_schema.py\", line 1038, in match_type\n",
      "    return self._unknown_type_schema(obj)\n",
      "  File \"c:\\anaconda3\\envs\\cv2\\lib\\site-packages\\pydantic\\_internal\\_generate_schema.py\", line 558, in _unknown_type_schema\n",
      "    raise PydanticSchemaGenerationError(\n",
      "pydantic.errors.PydanticSchemaGenerationError: Unable to generate pydantic-core schema for <class 'starlette.requests.Request'>. Set `arbitrary_types_allowed=True` in the model_config to ignore this error or implement `__get_pydantic_core_schema__` on your type to fully support it.\n",
      "\n",
      "If you got this error by calling handler(<some type>) within `__get_pydantic_core_schema__` then you likely need to call `handler.generate_schema(<some type>)` since we do not call `__get_pydantic_core_schema__` on `<some type>` otherwise to avoid infinite recursion.\n",
      "\n",
      "For further information visit https://errors.pydantic.dev/2.9/u/schema-for-unknown-type\n",
      "ERROR:    Exception in ASGI application\n",
      "Traceback (most recent call last):\n",
      "  File \"c:\\anaconda3\\envs\\cv2\\lib\\site-packages\\pydantic\\type_adapter.py\", line 270, in _init_core_attrs\n",
      "    self._core_schema = _getattr_no_parents(self._type, '__pydantic_core_schema__')\n",
      "  File \"c:\\anaconda3\\envs\\cv2\\lib\\site-packages\\pydantic\\type_adapter.py\", line 112, in _getattr_no_parents\n",
      "    raise AttributeError(attribute)\n",
      "AttributeError: __pydantic_core_schema__\n",
      "\n",
      "During handling of the above exception, another exception occurred:\n",
      "\n",
      "Traceback (most recent call last):\n",
      "  File \"C:\\Users\\shjung\\AppData\\Roaming\\Python\\Python38\\site-packages\\uvicorn\\protocols\\http\\h11_impl.py\", line 406, in run_asgi\n",
      "    result = await app(  # type: ignore[func-returns-value]\n",
      "  File \"C:\\Users\\shjung\\AppData\\Roaming\\Python\\Python38\\site-packages\\uvicorn\\middleware\\proxy_headers.py\", line 70, in __call__\n",
      "    return await self.app(scope, receive, send)\n",
      "  File \"C:\\Users\\shjung\\AppData\\Roaming\\Python\\Python38\\site-packages\\fastapi\\applications.py\", line 1054, in __call__\n",
      "    await super().__call__(scope, receive, send)\n",
      "  File \"C:\\Users\\shjung\\AppData\\Roaming\\Python\\Python38\\site-packages\\starlette\\applications.py\", line 113, in __call__\n",
      "    await self.middleware_stack(scope, receive, send)\n",
      "  File \"C:\\Users\\shjung\\AppData\\Roaming\\Python\\Python38\\site-packages\\starlette\\middleware\\errors.py\", line 187, in __call__\n",
      "    raise exc\n",
      "  File \"C:\\Users\\shjung\\AppData\\Roaming\\Python\\Python38\\site-packages\\starlette\\middleware\\errors.py\", line 165, in __call__\n",
      "    await self.app(scope, receive, _send)\n",
      "  File \"C:\\Users\\shjung\\AppData\\Roaming\\Python\\Python38\\site-packages\\starlette\\middleware\\cors.py\", line 93, in __call__\n",
      "    await self.simple_response(scope, receive, send, request_headers=headers)\n",
      "  File \"C:\\Users\\shjung\\AppData\\Roaming\\Python\\Python38\\site-packages\\starlette\\middleware\\cors.py\", line 144, in simple_response\n",
      "    await self.app(scope, receive, send)\n",
      "  File \"C:\\Users\\shjung\\AppData\\Roaming\\Python\\Python38\\site-packages\\starlette\\middleware\\exceptions.py\", line 62, in __call__\n",
      "    await wrap_app_handling_exceptions(self.app, conn)(scope, receive, send)\n",
      "  File \"C:\\Users\\shjung\\AppData\\Roaming\\Python\\Python38\\site-packages\\starlette\\_exception_handler.py\", line 62, in wrapped_app\n",
      "    raise exc\n",
      "  File \"C:\\Users\\shjung\\AppData\\Roaming\\Python\\Python38\\site-packages\\starlette\\_exception_handler.py\", line 51, in wrapped_app\n",
      "    await app(scope, receive, sender)\n",
      "  File \"C:\\Users\\shjung\\AppData\\Roaming\\Python\\Python38\\site-packages\\starlette\\routing.py\", line 715, in __call__\n",
      "    await self.middleware_stack(scope, receive, send)\n",
      "  File \"C:\\Users\\shjung\\AppData\\Roaming\\Python\\Python38\\site-packages\\starlette\\routing.py\", line 735, in app\n",
      "    await route.handle(scope, receive, send)\n",
      "  File \"C:\\Users\\shjung\\AppData\\Roaming\\Python\\Python38\\site-packages\\starlette\\routing.py\", line 288, in handle\n",
      "    await self.app(scope, receive, send)\n",
      "  File \"C:\\Users\\shjung\\AppData\\Roaming\\Python\\Python38\\site-packages\\starlette\\routing.py\", line 76, in app\n",
      "    await wrap_app_handling_exceptions(app, request)(scope, receive, send)\n",
      "  File \"C:\\Users\\shjung\\AppData\\Roaming\\Python\\Python38\\site-packages\\starlette\\_exception_handler.py\", line 62, in wrapped_app\n",
      "    raise exc\n",
      "  File \"C:\\Users\\shjung\\AppData\\Roaming\\Python\\Python38\\site-packages\\starlette\\_exception_handler.py\", line 51, in wrapped_app\n",
      "    await app(scope, receive, sender)\n",
      "  File \"C:\\Users\\shjung\\AppData\\Roaming\\Python\\Python38\\site-packages\\starlette\\routing.py\", line 73, in app\n",
      "    response = await f(request)\n",
      "  File \"C:\\Users\\shjung\\AppData\\Roaming\\Python\\Python38\\site-packages\\fastapi\\routing.py\", line 291, in app\n",
      "    solved_result = await solve_dependencies(\n",
      "  File \"C:\\Users\\shjung\\AppData\\Roaming\\Python\\Python38\\site-packages\\fastapi\\dependencies\\utils.py\", line 656, in solve_dependencies\n",
      "    ) = await request_body_to_args(  # body_params checked above\n",
      "  File \"C:\\Users\\shjung\\AppData\\Roaming\\Python\\Python38\\site-packages\\fastapi\\dependencies\\utils.py\", line 881, in request_body_to_args\n",
      "    fields_to_extract = get_cached_model_fields(first_field.type_)\n",
      "  File \"C:\\Users\\shjung\\AppData\\Roaming\\Python\\Python38\\site-packages\\fastapi\\_compat.py\", line 657, in get_cached_model_fields\n",
      "    return get_model_fields(model)\n",
      "  File \"C:\\Users\\shjung\\AppData\\Roaming\\Python\\Python38\\site-packages\\fastapi\\_compat.py\", line 284, in get_model_fields\n",
      "    return [\n",
      "  File \"C:\\Users\\shjung\\AppData\\Roaming\\Python\\Python38\\site-packages\\fastapi\\_compat.py\", line 285, in <listcomp>\n",
      "    ModelField(field_info=field_info, name=name)\n",
      "  File \"<string>\", line 6, in __init__\n",
      "  File \"C:\\Users\\shjung\\AppData\\Roaming\\Python\\Python38\\site-packages\\fastapi\\_compat.py\", line 110, in __post_init__\n",
      "    self._type_adapter: TypeAdapter[Any] = TypeAdapter(\n",
      "  File \"c:\\anaconda3\\envs\\cv2\\lib\\site-packages\\pydantic\\type_adapter.py\", line 257, in __init__\n",
      "    self._init_core_attrs(rebuild_mocks=False)\n",
      "  File \"c:\\anaconda3\\envs\\cv2\\lib\\site-packages\\pydantic\\type_adapter.py\", line 135, in wrapped\n",
      "    return func(self, *args, **kwargs)\n",
      "  File \"c:\\anaconda3\\envs\\cv2\\lib\\site-packages\\pydantic\\type_adapter.py\", line 277, in _init_core_attrs\n",
      "    self._core_schema = _get_schema(self._type, config_wrapper, parent_depth=self._parent_depth)\n",
      "  File \"c:\\anaconda3\\envs\\cv2\\lib\\site-packages\\pydantic\\type_adapter.py\", line 95, in _get_schema\n",
      "    schema = gen.generate_schema(type_)\n",
      "  File \"c:\\anaconda3\\envs\\cv2\\lib\\site-packages\\pydantic\\_internal\\_generate_schema.py\", line 655, in generate_schema\n",
      "    schema = self._generate_schema_inner(obj)\n",
      "  File \"c:\\anaconda3\\envs\\cv2\\lib\\site-packages\\pydantic\\_internal\\_generate_schema.py\", line 908, in _generate_schema_inner\n",
      "    return self._annotated_schema(obj)\n",
      "  File \"c:\\anaconda3\\envs\\cv2\\lib\\site-packages\\pydantic\\_internal\\_generate_schema.py\", line 2028, in _annotated_schema\n",
      "    schema = self._apply_annotations(source_type, annotations)\n",
      "  File \"c:\\anaconda3\\envs\\cv2\\lib\\site-packages\\pydantic\\_internal\\_generate_schema.py\", line 2107, in _apply_annotations\n",
      "    schema = get_inner_schema(source_type)\n",
      "  File \"c:\\anaconda3\\envs\\cv2\\lib\\site-packages\\pydantic\\_internal\\_schema_generation_shared.py\", line 83, in __call__\n",
      "    schema = self._handler(source_type)\n",
      "  File \"c:\\anaconda3\\envs\\cv2\\lib\\site-packages\\pydantic\\_internal\\_generate_schema.py\", line 2189, in new_handler\n",
      "    schema = metadata_get_schema(source, get_inner_schema)\n",
      "  File \"c:\\anaconda3\\envs\\cv2\\lib\\site-packages\\pydantic\\_internal\\_generate_schema.py\", line 2185, in <lambda>\n",
      "    lambda source, handler: handler(source)\n",
      "  File \"c:\\anaconda3\\envs\\cv2\\lib\\site-packages\\pydantic\\_internal\\_schema_generation_shared.py\", line 83, in __call__\n",
      "    schema = self._handler(source_type)\n",
      "  File \"c:\\anaconda3\\envs\\cv2\\lib\\site-packages\\pydantic\\_internal\\_generate_schema.py\", line 2088, in inner_handler\n",
      "    schema = self._generate_schema_inner(obj)\n",
      "  File \"c:\\anaconda3\\envs\\cv2\\lib\\site-packages\\pydantic\\_internal\\_generate_schema.py\", line 929, in _generate_schema_inner\n",
      "    return self.match_type(obj)\n",
      "  File \"c:\\anaconda3\\envs\\cv2\\lib\\site-packages\\pydantic\\_internal\\_generate_schema.py\", line 1029, in match_type\n",
      "    return self._match_generic_type(obj, origin)\n",
      "  File \"c:\\anaconda3\\envs\\cv2\\lib\\site-packages\\pydantic\\_internal\\_generate_schema.py\", line 1058, in _match_generic_type\n",
      "    return self._union_schema(obj)\n",
      "  File \"c:\\anaconda3\\envs\\cv2\\lib\\site-packages\\pydantic\\_internal\\_generate_schema.py\", line 1378, in _union_schema\n",
      "    choices.append(self.generate_schema(arg))\n",
      "  File \"c:\\anaconda3\\envs\\cv2\\lib\\site-packages\\pydantic\\_internal\\_generate_schema.py\", line 655, in generate_schema\n",
      "    schema = self._generate_schema_inner(obj)\n",
      "  File \"c:\\anaconda3\\envs\\cv2\\lib\\site-packages\\pydantic\\_internal\\_generate_schema.py\", line 929, in _generate_schema_inner\n",
      "    return self.match_type(obj)\n",
      "  File \"c:\\anaconda3\\envs\\cv2\\lib\\site-packages\\pydantic\\_internal\\_generate_schema.py\", line 1038, in match_type\n",
      "    return self._unknown_type_schema(obj)\n",
      "  File \"c:\\anaconda3\\envs\\cv2\\lib\\site-packages\\pydantic\\_internal\\_generate_schema.py\", line 558, in _unknown_type_schema\n",
      "    raise PydanticSchemaGenerationError(\n",
      "pydantic.errors.PydanticSchemaGenerationError: Unable to generate pydantic-core schema for <class 'starlette.requests.Request'>. Set `arbitrary_types_allowed=True` in the model_config to ignore this error or implement `__get_pydantic_core_schema__` on your type to fully support it.\n",
      "\n",
      "If you got this error by calling handler(<some type>) within `__get_pydantic_core_schema__` then you likely need to call `handler.generate_schema(<some type>)` since we do not call `__get_pydantic_core_schema__` on `<some type>` otherwise to avoid infinite recursion.\n",
      "\n",
      "For further information visit https://errors.pydantic.dev/2.9/u/schema-for-unknown-type\n",
      "ERROR:    Exception in ASGI application\n",
      "Traceback (most recent call last):\n",
      "  File \"c:\\anaconda3\\envs\\cv2\\lib\\site-packages\\pydantic\\type_adapter.py\", line 270, in _init_core_attrs\n",
      "    self._core_schema = _getattr_no_parents(self._type, '__pydantic_core_schema__')\n",
      "  File \"c:\\anaconda3\\envs\\cv2\\lib\\site-packages\\pydantic\\type_adapter.py\", line 112, in _getattr_no_parents\n",
      "    raise AttributeError(attribute)\n",
      "AttributeError: __pydantic_core_schema__\n",
      "\n",
      "During handling of the above exception, another exception occurred:\n",
      "\n",
      "Traceback (most recent call last):\n",
      "  File \"C:\\Users\\shjung\\AppData\\Roaming\\Python\\Python38\\site-packages\\uvicorn\\protocols\\http\\h11_impl.py\", line 406, in run_asgi\n",
      "    result = await app(  # type: ignore[func-returns-value]\n",
      "  File \"C:\\Users\\shjung\\AppData\\Roaming\\Python\\Python38\\site-packages\\uvicorn\\middleware\\proxy_headers.py\", line 70, in __call__\n",
      "    return await self.app(scope, receive, send)\n",
      "  File \"C:\\Users\\shjung\\AppData\\Roaming\\Python\\Python38\\site-packages\\fastapi\\applications.py\", line 1054, in __call__\n",
      "    await super().__call__(scope, receive, send)\n",
      "  File \"C:\\Users\\shjung\\AppData\\Roaming\\Python\\Python38\\site-packages\\starlette\\applications.py\", line 113, in __call__\n",
      "    await self.middleware_stack(scope, receive, send)\n",
      "  File \"C:\\Users\\shjung\\AppData\\Roaming\\Python\\Python38\\site-packages\\starlette\\middleware\\errors.py\", line 187, in __call__\n",
      "    raise exc\n",
      "  File \"C:\\Users\\shjung\\AppData\\Roaming\\Python\\Python38\\site-packages\\starlette\\middleware\\errors.py\", line 165, in __call__\n",
      "    await self.app(scope, receive, _send)\n",
      "  File \"C:\\Users\\shjung\\AppData\\Roaming\\Python\\Python38\\site-packages\\starlette\\middleware\\cors.py\", line 93, in __call__\n",
      "    await self.simple_response(scope, receive, send, request_headers=headers)\n",
      "  File \"C:\\Users\\shjung\\AppData\\Roaming\\Python\\Python38\\site-packages\\starlette\\middleware\\cors.py\", line 144, in simple_response\n",
      "    await self.app(scope, receive, send)\n",
      "  File \"C:\\Users\\shjung\\AppData\\Roaming\\Python\\Python38\\site-packages\\starlette\\middleware\\exceptions.py\", line 62, in __call__\n",
      "    await wrap_app_handling_exceptions(self.app, conn)(scope, receive, send)\n",
      "  File \"C:\\Users\\shjung\\AppData\\Roaming\\Python\\Python38\\site-packages\\starlette\\_exception_handler.py\", line 62, in wrapped_app\n",
      "    raise exc\n",
      "  File \"C:\\Users\\shjung\\AppData\\Roaming\\Python\\Python38\\site-packages\\starlette\\_exception_handler.py\", line 51, in wrapped_app\n",
      "    await app(scope, receive, sender)\n",
      "  File \"C:\\Users\\shjung\\AppData\\Roaming\\Python\\Python38\\site-packages\\starlette\\routing.py\", line 715, in __call__\n",
      "    await self.middleware_stack(scope, receive, send)\n",
      "  File \"C:\\Users\\shjung\\AppData\\Roaming\\Python\\Python38\\site-packages\\starlette\\routing.py\", line 735, in app\n",
      "    await route.handle(scope, receive, send)\n",
      "  File \"C:\\Users\\shjung\\AppData\\Roaming\\Python\\Python38\\site-packages\\starlette\\routing.py\", line 288, in handle\n",
      "    await self.app(scope, receive, send)\n",
      "  File \"C:\\Users\\shjung\\AppData\\Roaming\\Python\\Python38\\site-packages\\starlette\\routing.py\", line 76, in app\n",
      "    await wrap_app_handling_exceptions(app, request)(scope, receive, send)\n",
      "  File \"C:\\Users\\shjung\\AppData\\Roaming\\Python\\Python38\\site-packages\\starlette\\_exception_handler.py\", line 62, in wrapped_app\n",
      "    raise exc\n",
      "  File \"C:\\Users\\shjung\\AppData\\Roaming\\Python\\Python38\\site-packages\\starlette\\_exception_handler.py\", line 51, in wrapped_app\n",
      "    await app(scope, receive, sender)\n",
      "  File \"C:\\Users\\shjung\\AppData\\Roaming\\Python\\Python38\\site-packages\\starlette\\routing.py\", line 73, in app\n",
      "    response = await f(request)\n",
      "  File \"C:\\Users\\shjung\\AppData\\Roaming\\Python\\Python38\\site-packages\\fastapi\\routing.py\", line 291, in app\n",
      "    solved_result = await solve_dependencies(\n",
      "  File \"C:\\Users\\shjung\\AppData\\Roaming\\Python\\Python38\\site-packages\\fastapi\\dependencies\\utils.py\", line 656, in solve_dependencies\n",
      "    ) = await request_body_to_args(  # body_params checked above\n",
      "  File \"C:\\Users\\shjung\\AppData\\Roaming\\Python\\Python38\\site-packages\\fastapi\\dependencies\\utils.py\", line 881, in request_body_to_args\n",
      "    fields_to_extract = get_cached_model_fields(first_field.type_)\n",
      "  File \"C:\\Users\\shjung\\AppData\\Roaming\\Python\\Python38\\site-packages\\fastapi\\_compat.py\", line 657, in get_cached_model_fields\n",
      "    return get_model_fields(model)\n",
      "  File \"C:\\Users\\shjung\\AppData\\Roaming\\Python\\Python38\\site-packages\\fastapi\\_compat.py\", line 284, in get_model_fields\n",
      "    return [\n",
      "  File \"C:\\Users\\shjung\\AppData\\Roaming\\Python\\Python38\\site-packages\\fastapi\\_compat.py\", line 285, in <listcomp>\n",
      "    ModelField(field_info=field_info, name=name)\n",
      "  File \"<string>\", line 6, in __init__\n",
      "  File \"C:\\Users\\shjung\\AppData\\Roaming\\Python\\Python38\\site-packages\\fastapi\\_compat.py\", line 110, in __post_init__\n",
      "    self._type_adapter: TypeAdapter[Any] = TypeAdapter(\n",
      "  File \"c:\\anaconda3\\envs\\cv2\\lib\\site-packages\\pydantic\\type_adapter.py\", line 257, in __init__\n",
      "    self._init_core_attrs(rebuild_mocks=False)\n",
      "  File \"c:\\anaconda3\\envs\\cv2\\lib\\site-packages\\pydantic\\type_adapter.py\", line 135, in wrapped\n",
      "    return func(self, *args, **kwargs)\n",
      "  File \"c:\\anaconda3\\envs\\cv2\\lib\\site-packages\\pydantic\\type_adapter.py\", line 277, in _init_core_attrs\n",
      "    self._core_schema = _get_schema(self._type, config_wrapper, parent_depth=self._parent_depth)\n",
      "  File \"c:\\anaconda3\\envs\\cv2\\lib\\site-packages\\pydantic\\type_adapter.py\", line 95, in _get_schema\n",
      "    schema = gen.generate_schema(type_)\n",
      "  File \"c:\\anaconda3\\envs\\cv2\\lib\\site-packages\\pydantic\\_internal\\_generate_schema.py\", line 655, in generate_schema\n",
      "    schema = self._generate_schema_inner(obj)\n",
      "  File \"c:\\anaconda3\\envs\\cv2\\lib\\site-packages\\pydantic\\_internal\\_generate_schema.py\", line 908, in _generate_schema_inner\n",
      "    return self._annotated_schema(obj)\n",
      "  File \"c:\\anaconda3\\envs\\cv2\\lib\\site-packages\\pydantic\\_internal\\_generate_schema.py\", line 2028, in _annotated_schema\n",
      "    schema = self._apply_annotations(source_type, annotations)\n",
      "  File \"c:\\anaconda3\\envs\\cv2\\lib\\site-packages\\pydantic\\_internal\\_generate_schema.py\", line 2107, in _apply_annotations\n",
      "    schema = get_inner_schema(source_type)\n",
      "  File \"c:\\anaconda3\\envs\\cv2\\lib\\site-packages\\pydantic\\_internal\\_schema_generation_shared.py\", line 83, in __call__\n",
      "    schema = self._handler(source_type)\n",
      "  File \"c:\\anaconda3\\envs\\cv2\\lib\\site-packages\\pydantic\\_internal\\_generate_schema.py\", line 2189, in new_handler\n",
      "    schema = metadata_get_schema(source, get_inner_schema)\n",
      "  File \"c:\\anaconda3\\envs\\cv2\\lib\\site-packages\\pydantic\\_internal\\_generate_schema.py\", line 2185, in <lambda>\n",
      "    lambda source, handler: handler(source)\n",
      "  File \"c:\\anaconda3\\envs\\cv2\\lib\\site-packages\\pydantic\\_internal\\_schema_generation_shared.py\", line 83, in __call__\n",
      "    schema = self._handler(source_type)\n",
      "  File \"c:\\anaconda3\\envs\\cv2\\lib\\site-packages\\pydantic\\_internal\\_generate_schema.py\", line 2088, in inner_handler\n",
      "    schema = self._generate_schema_inner(obj)\n",
      "  File \"c:\\anaconda3\\envs\\cv2\\lib\\site-packages\\pydantic\\_internal\\_generate_schema.py\", line 929, in _generate_schema_inner\n",
      "    return self.match_type(obj)\n",
      "  File \"c:\\anaconda3\\envs\\cv2\\lib\\site-packages\\pydantic\\_internal\\_generate_schema.py\", line 1029, in match_type\n",
      "    return self._match_generic_type(obj, origin)\n",
      "  File \"c:\\anaconda3\\envs\\cv2\\lib\\site-packages\\pydantic\\_internal\\_generate_schema.py\", line 1058, in _match_generic_type\n",
      "    return self._union_schema(obj)\n",
      "  File \"c:\\anaconda3\\envs\\cv2\\lib\\site-packages\\pydantic\\_internal\\_generate_schema.py\", line 1378, in _union_schema\n",
      "    choices.append(self.generate_schema(arg))\n",
      "  File \"c:\\anaconda3\\envs\\cv2\\lib\\site-packages\\pydantic\\_internal\\_generate_schema.py\", line 655, in generate_schema\n",
      "    schema = self._generate_schema_inner(obj)\n",
      "  File \"c:\\anaconda3\\envs\\cv2\\lib\\site-packages\\pydantic\\_internal\\_generate_schema.py\", line 929, in _generate_schema_inner\n",
      "    return self.match_type(obj)\n",
      "  File \"c:\\anaconda3\\envs\\cv2\\lib\\site-packages\\pydantic\\_internal\\_generate_schema.py\", line 1038, in match_type\n",
      "    return self._unknown_type_schema(obj)\n",
      "  File \"c:\\anaconda3\\envs\\cv2\\lib\\site-packages\\pydantic\\_internal\\_generate_schema.py\", line 558, in _unknown_type_schema\n",
      "    raise PydanticSchemaGenerationError(\n",
      "pydantic.errors.PydanticSchemaGenerationError: Unable to generate pydantic-core schema for <class 'starlette.requests.Request'>. Set `arbitrary_types_allowed=True` in the model_config to ignore this error or implement `__get_pydantic_core_schema__` on your type to fully support it.\n",
      "\n",
      "If you got this error by calling handler(<some type>) within `__get_pydantic_core_schema__` then you likely need to call `handler.generate_schema(<some type>)` since we do not call `__get_pydantic_core_schema__` on `<some type>` otherwise to avoid infinite recursion.\n",
      "\n",
      "For further information visit https://errors.pydantic.dev/2.9/u/schema-for-unknown-type\n",
      "ERROR:    Exception in ASGI application\n",
      "Traceback (most recent call last):\n",
      "  File \"c:\\anaconda3\\envs\\cv2\\lib\\site-packages\\pydantic\\type_adapter.py\", line 270, in _init_core_attrs\n",
      "    self._core_schema = _getattr_no_parents(self._type, '__pydantic_core_schema__')\n",
      "  File \"c:\\anaconda3\\envs\\cv2\\lib\\site-packages\\pydantic\\type_adapter.py\", line 112, in _getattr_no_parents\n",
      "    raise AttributeError(attribute)\n",
      "AttributeError: __pydantic_core_schema__\n",
      "\n",
      "During handling of the above exception, another exception occurred:\n",
      "\n",
      "Traceback (most recent call last):\n",
      "  File \"C:\\Users\\shjung\\AppData\\Roaming\\Python\\Python38\\site-packages\\uvicorn\\protocols\\http\\h11_impl.py\", line 406, in run_asgi\n",
      "    result = await app(  # type: ignore[func-returns-value]\n",
      "  File \"C:\\Users\\shjung\\AppData\\Roaming\\Python\\Python38\\site-packages\\uvicorn\\middleware\\proxy_headers.py\", line 70, in __call__\n",
      "    return await self.app(scope, receive, send)\n",
      "  File \"C:\\Users\\shjung\\AppData\\Roaming\\Python\\Python38\\site-packages\\fastapi\\applications.py\", line 1054, in __call__\n",
      "    await super().__call__(scope, receive, send)\n",
      "  File \"C:\\Users\\shjung\\AppData\\Roaming\\Python\\Python38\\site-packages\\starlette\\applications.py\", line 113, in __call__\n",
      "    await self.middleware_stack(scope, receive, send)\n",
      "  File \"C:\\Users\\shjung\\AppData\\Roaming\\Python\\Python38\\site-packages\\starlette\\middleware\\errors.py\", line 187, in __call__\n",
      "    raise exc\n",
      "  File \"C:\\Users\\shjung\\AppData\\Roaming\\Python\\Python38\\site-packages\\starlette\\middleware\\errors.py\", line 165, in __call__\n",
      "    await self.app(scope, receive, _send)\n",
      "  File \"C:\\Users\\shjung\\AppData\\Roaming\\Python\\Python38\\site-packages\\starlette\\middleware\\cors.py\", line 93, in __call__\n",
      "    await self.simple_response(scope, receive, send, request_headers=headers)\n",
      "  File \"C:\\Users\\shjung\\AppData\\Roaming\\Python\\Python38\\site-packages\\starlette\\middleware\\cors.py\", line 144, in simple_response\n",
      "    await self.app(scope, receive, send)\n",
      "  File \"C:\\Users\\shjung\\AppData\\Roaming\\Python\\Python38\\site-packages\\starlette\\middleware\\exceptions.py\", line 62, in __call__\n",
      "    await wrap_app_handling_exceptions(self.app, conn)(scope, receive, send)\n",
      "  File \"C:\\Users\\shjung\\AppData\\Roaming\\Python\\Python38\\site-packages\\starlette\\_exception_handler.py\", line 62, in wrapped_app\n",
      "    raise exc\n",
      "  File \"C:\\Users\\shjung\\AppData\\Roaming\\Python\\Python38\\site-packages\\starlette\\_exception_handler.py\", line 51, in wrapped_app\n",
      "    await app(scope, receive, sender)\n",
      "  File \"C:\\Users\\shjung\\AppData\\Roaming\\Python\\Python38\\site-packages\\starlette\\routing.py\", line 715, in __call__\n",
      "    await self.middleware_stack(scope, receive, send)\n",
      "  File \"C:\\Users\\shjung\\AppData\\Roaming\\Python\\Python38\\site-packages\\starlette\\routing.py\", line 735, in app\n",
      "    await route.handle(scope, receive, send)\n",
      "  File \"C:\\Users\\shjung\\AppData\\Roaming\\Python\\Python38\\site-packages\\starlette\\routing.py\", line 288, in handle\n",
      "    await self.app(scope, receive, send)\n",
      "  File \"C:\\Users\\shjung\\AppData\\Roaming\\Python\\Python38\\site-packages\\starlette\\routing.py\", line 76, in app\n",
      "    await wrap_app_handling_exceptions(app, request)(scope, receive, send)\n",
      "  File \"C:\\Users\\shjung\\AppData\\Roaming\\Python\\Python38\\site-packages\\starlette\\_exception_handler.py\", line 62, in wrapped_app\n",
      "    raise exc\n",
      "  File \"C:\\Users\\shjung\\AppData\\Roaming\\Python\\Python38\\site-packages\\starlette\\_exception_handler.py\", line 51, in wrapped_app\n",
      "    await app(scope, receive, sender)\n",
      "  File \"C:\\Users\\shjung\\AppData\\Roaming\\Python\\Python38\\site-packages\\starlette\\routing.py\", line 73, in app\n",
      "    response = await f(request)\n",
      "  File \"C:\\Users\\shjung\\AppData\\Roaming\\Python\\Python38\\site-packages\\fastapi\\routing.py\", line 291, in app\n",
      "    solved_result = await solve_dependencies(\n",
      "  File \"C:\\Users\\shjung\\AppData\\Roaming\\Python\\Python38\\site-packages\\fastapi\\dependencies\\utils.py\", line 656, in solve_dependencies\n",
      "    ) = await request_body_to_args(  # body_params checked above\n",
      "  File \"C:\\Users\\shjung\\AppData\\Roaming\\Python\\Python38\\site-packages\\fastapi\\dependencies\\utils.py\", line 881, in request_body_to_args\n",
      "    fields_to_extract = get_cached_model_fields(first_field.type_)\n",
      "  File \"C:\\Users\\shjung\\AppData\\Roaming\\Python\\Python38\\site-packages\\fastapi\\_compat.py\", line 657, in get_cached_model_fields\n",
      "    return get_model_fields(model)\n",
      "  File \"C:\\Users\\shjung\\AppData\\Roaming\\Python\\Python38\\site-packages\\fastapi\\_compat.py\", line 284, in get_model_fields\n",
      "    return [\n",
      "  File \"C:\\Users\\shjung\\AppData\\Roaming\\Python\\Python38\\site-packages\\fastapi\\_compat.py\", line 285, in <listcomp>\n",
      "    ModelField(field_info=field_info, name=name)\n",
      "  File \"<string>\", line 6, in __init__\n",
      "  File \"C:\\Users\\shjung\\AppData\\Roaming\\Python\\Python38\\site-packages\\fastapi\\_compat.py\", line 110, in __post_init__\n",
      "    self._type_adapter: TypeAdapter[Any] = TypeAdapter(\n",
      "  File \"c:\\anaconda3\\envs\\cv2\\lib\\site-packages\\pydantic\\type_adapter.py\", line 257, in __init__\n",
      "    self._init_core_attrs(rebuild_mocks=False)\n",
      "  File \"c:\\anaconda3\\envs\\cv2\\lib\\site-packages\\pydantic\\type_adapter.py\", line 135, in wrapped\n",
      "    return func(self, *args, **kwargs)\n",
      "  File \"c:\\anaconda3\\envs\\cv2\\lib\\site-packages\\pydantic\\type_adapter.py\", line 277, in _init_core_attrs\n",
      "    self._core_schema = _get_schema(self._type, config_wrapper, parent_depth=self._parent_depth)\n",
      "  File \"c:\\anaconda3\\envs\\cv2\\lib\\site-packages\\pydantic\\type_adapter.py\", line 95, in _get_schema\n",
      "    schema = gen.generate_schema(type_)\n",
      "  File \"c:\\anaconda3\\envs\\cv2\\lib\\site-packages\\pydantic\\_internal\\_generate_schema.py\", line 655, in generate_schema\n",
      "    schema = self._generate_schema_inner(obj)\n",
      "  File \"c:\\anaconda3\\envs\\cv2\\lib\\site-packages\\pydantic\\_internal\\_generate_schema.py\", line 908, in _generate_schema_inner\n",
      "    return self._annotated_schema(obj)\n",
      "  File \"c:\\anaconda3\\envs\\cv2\\lib\\site-packages\\pydantic\\_internal\\_generate_schema.py\", line 2028, in _annotated_schema\n",
      "    schema = self._apply_annotations(source_type, annotations)\n",
      "  File \"c:\\anaconda3\\envs\\cv2\\lib\\site-packages\\pydantic\\_internal\\_generate_schema.py\", line 2107, in _apply_annotations\n",
      "    schema = get_inner_schema(source_type)\n",
      "  File \"c:\\anaconda3\\envs\\cv2\\lib\\site-packages\\pydantic\\_internal\\_schema_generation_shared.py\", line 83, in __call__\n",
      "    schema = self._handler(source_type)\n",
      "  File \"c:\\anaconda3\\envs\\cv2\\lib\\site-packages\\pydantic\\_internal\\_generate_schema.py\", line 2189, in new_handler\n",
      "    schema = metadata_get_schema(source, get_inner_schema)\n",
      "  File \"c:\\anaconda3\\envs\\cv2\\lib\\site-packages\\pydantic\\_internal\\_generate_schema.py\", line 2185, in <lambda>\n",
      "    lambda source, handler: handler(source)\n",
      "  File \"c:\\anaconda3\\envs\\cv2\\lib\\site-packages\\pydantic\\_internal\\_schema_generation_shared.py\", line 83, in __call__\n",
      "    schema = self._handler(source_type)\n",
      "  File \"c:\\anaconda3\\envs\\cv2\\lib\\site-packages\\pydantic\\_internal\\_generate_schema.py\", line 2088, in inner_handler\n",
      "    schema = self._generate_schema_inner(obj)\n",
      "  File \"c:\\anaconda3\\envs\\cv2\\lib\\site-packages\\pydantic\\_internal\\_generate_schema.py\", line 929, in _generate_schema_inner\n",
      "    return self.match_type(obj)\n",
      "  File \"c:\\anaconda3\\envs\\cv2\\lib\\site-packages\\pydantic\\_internal\\_generate_schema.py\", line 1029, in match_type\n",
      "    return self._match_generic_type(obj, origin)\n",
      "  File \"c:\\anaconda3\\envs\\cv2\\lib\\site-packages\\pydantic\\_internal\\_generate_schema.py\", line 1058, in _match_generic_type\n",
      "    return self._union_schema(obj)\n",
      "  File \"c:\\anaconda3\\envs\\cv2\\lib\\site-packages\\pydantic\\_internal\\_generate_schema.py\", line 1378, in _union_schema\n",
      "    choices.append(self.generate_schema(arg))\n",
      "  File \"c:\\anaconda3\\envs\\cv2\\lib\\site-packages\\pydantic\\_internal\\_generate_schema.py\", line 655, in generate_schema\n",
      "    schema = self._generate_schema_inner(obj)\n",
      "  File \"c:\\anaconda3\\envs\\cv2\\lib\\site-packages\\pydantic\\_internal\\_generate_schema.py\", line 929, in _generate_schema_inner\n",
      "    return self.match_type(obj)\n",
      "  File \"c:\\anaconda3\\envs\\cv2\\lib\\site-packages\\pydantic\\_internal\\_generate_schema.py\", line 1038, in match_type\n",
      "    return self._unknown_type_schema(obj)\n",
      "  File \"c:\\anaconda3\\envs\\cv2\\lib\\site-packages\\pydantic\\_internal\\_generate_schema.py\", line 558, in _unknown_type_schema\n",
      "    raise PydanticSchemaGenerationError(\n",
      "pydantic.errors.PydanticSchemaGenerationError: Unable to generate pydantic-core schema for <class 'starlette.requests.Request'>. Set `arbitrary_types_allowed=True` in the model_config to ignore this error or implement `__get_pydantic_core_schema__` on your type to fully support it.\n",
      "\n",
      "If you got this error by calling handler(<some type>) within `__get_pydantic_core_schema__` then you likely need to call `handler.generate_schema(<some type>)` since we do not call `__get_pydantic_core_schema__` on `<some type>` otherwise to avoid infinite recursion.\n",
      "\n",
      "For further information visit https://errors.pydantic.dev/2.9/u/schema-for-unknown-type\n",
      "ERROR:    Exception in ASGI application\n",
      "Traceback (most recent call last):\n",
      "  File \"c:\\anaconda3\\envs\\cv2\\lib\\site-packages\\pydantic\\type_adapter.py\", line 270, in _init_core_attrs\n",
      "    self._core_schema = _getattr_no_parents(self._type, '__pydantic_core_schema__')\n",
      "  File \"c:\\anaconda3\\envs\\cv2\\lib\\site-packages\\pydantic\\type_adapter.py\", line 112, in _getattr_no_parents\n",
      "    raise AttributeError(attribute)\n",
      "AttributeError: __pydantic_core_schema__\n",
      "\n",
      "During handling of the above exception, another exception occurred:\n",
      "\n",
      "Traceback (most recent call last):\n",
      "  File \"C:\\Users\\shjung\\AppData\\Roaming\\Python\\Python38\\site-packages\\uvicorn\\protocols\\http\\h11_impl.py\", line 406, in run_asgi\n",
      "    result = await app(  # type: ignore[func-returns-value]\n",
      "  File \"C:\\Users\\shjung\\AppData\\Roaming\\Python\\Python38\\site-packages\\uvicorn\\middleware\\proxy_headers.py\", line 70, in __call__\n",
      "    return await self.app(scope, receive, send)\n",
      "  File \"C:\\Users\\shjung\\AppData\\Roaming\\Python\\Python38\\site-packages\\fastapi\\applications.py\", line 1054, in __call__\n",
      "    await super().__call__(scope, receive, send)\n",
      "  File \"C:\\Users\\shjung\\AppData\\Roaming\\Python\\Python38\\site-packages\\starlette\\applications.py\", line 113, in __call__\n",
      "    await self.middleware_stack(scope, receive, send)\n",
      "  File \"C:\\Users\\shjung\\AppData\\Roaming\\Python\\Python38\\site-packages\\starlette\\middleware\\errors.py\", line 187, in __call__\n",
      "    raise exc\n",
      "  File \"C:\\Users\\shjung\\AppData\\Roaming\\Python\\Python38\\site-packages\\starlette\\middleware\\errors.py\", line 165, in __call__\n",
      "    await self.app(scope, receive, _send)\n",
      "  File \"C:\\Users\\shjung\\AppData\\Roaming\\Python\\Python38\\site-packages\\starlette\\middleware\\cors.py\", line 93, in __call__\n",
      "    await self.simple_response(scope, receive, send, request_headers=headers)\n",
      "  File \"C:\\Users\\shjung\\AppData\\Roaming\\Python\\Python38\\site-packages\\starlette\\middleware\\cors.py\", line 144, in simple_response\n",
      "    await self.app(scope, receive, send)\n",
      "  File \"C:\\Users\\shjung\\AppData\\Roaming\\Python\\Python38\\site-packages\\starlette\\middleware\\exceptions.py\", line 62, in __call__\n",
      "    await wrap_app_handling_exceptions(self.app, conn)(scope, receive, send)\n",
      "  File \"C:\\Users\\shjung\\AppData\\Roaming\\Python\\Python38\\site-packages\\starlette\\_exception_handler.py\", line 62, in wrapped_app\n",
      "    raise exc\n",
      "  File \"C:\\Users\\shjung\\AppData\\Roaming\\Python\\Python38\\site-packages\\starlette\\_exception_handler.py\", line 51, in wrapped_app\n",
      "    await app(scope, receive, sender)\n",
      "  File \"C:\\Users\\shjung\\AppData\\Roaming\\Python\\Python38\\site-packages\\starlette\\routing.py\", line 715, in __call__\n",
      "    await self.middleware_stack(scope, receive, send)\n",
      "  File \"C:\\Users\\shjung\\AppData\\Roaming\\Python\\Python38\\site-packages\\starlette\\routing.py\", line 735, in app\n",
      "    await route.handle(scope, receive, send)\n",
      "  File \"C:\\Users\\shjung\\AppData\\Roaming\\Python\\Python38\\site-packages\\starlette\\routing.py\", line 288, in handle\n",
      "    await self.app(scope, receive, send)\n",
      "  File \"C:\\Users\\shjung\\AppData\\Roaming\\Python\\Python38\\site-packages\\starlette\\routing.py\", line 76, in app\n",
      "    await wrap_app_handling_exceptions(app, request)(scope, receive, send)\n",
      "  File \"C:\\Users\\shjung\\AppData\\Roaming\\Python\\Python38\\site-packages\\starlette\\_exception_handler.py\", line 62, in wrapped_app\n",
      "    raise exc\n",
      "  File \"C:\\Users\\shjung\\AppData\\Roaming\\Python\\Python38\\site-packages\\starlette\\_exception_handler.py\", line 51, in wrapped_app\n",
      "    await app(scope, receive, sender)\n",
      "  File \"C:\\Users\\shjung\\AppData\\Roaming\\Python\\Python38\\site-packages\\starlette\\routing.py\", line 73, in app\n",
      "    response = await f(request)\n",
      "  File \"C:\\Users\\shjung\\AppData\\Roaming\\Python\\Python38\\site-packages\\fastapi\\routing.py\", line 291, in app\n",
      "    solved_result = await solve_dependencies(\n",
      "  File \"C:\\Users\\shjung\\AppData\\Roaming\\Python\\Python38\\site-packages\\fastapi\\dependencies\\utils.py\", line 656, in solve_dependencies\n",
      "    ) = await request_body_to_args(  # body_params checked above\n",
      "  File \"C:\\Users\\shjung\\AppData\\Roaming\\Python\\Python38\\site-packages\\fastapi\\dependencies\\utils.py\", line 881, in request_body_to_args\n",
      "    fields_to_extract = get_cached_model_fields(first_field.type_)\n",
      "  File \"C:\\Users\\shjung\\AppData\\Roaming\\Python\\Python38\\site-packages\\fastapi\\_compat.py\", line 657, in get_cached_model_fields\n",
      "    return get_model_fields(model)\n",
      "  File \"C:\\Users\\shjung\\AppData\\Roaming\\Python\\Python38\\site-packages\\fastapi\\_compat.py\", line 284, in get_model_fields\n",
      "    return [\n",
      "  File \"C:\\Users\\shjung\\AppData\\Roaming\\Python\\Python38\\site-packages\\fastapi\\_compat.py\", line 285, in <listcomp>\n",
      "    ModelField(field_info=field_info, name=name)\n",
      "  File \"<string>\", line 6, in __init__\n",
      "  File \"C:\\Users\\shjung\\AppData\\Roaming\\Python\\Python38\\site-packages\\fastapi\\_compat.py\", line 110, in __post_init__\n",
      "    self._type_adapter: TypeAdapter[Any] = TypeAdapter(\n",
      "  File \"c:\\anaconda3\\envs\\cv2\\lib\\site-packages\\pydantic\\type_adapter.py\", line 257, in __init__\n",
      "    self._init_core_attrs(rebuild_mocks=False)\n",
      "  File \"c:\\anaconda3\\envs\\cv2\\lib\\site-packages\\pydantic\\type_adapter.py\", line 135, in wrapped\n",
      "    return func(self, *args, **kwargs)\n",
      "  File \"c:\\anaconda3\\envs\\cv2\\lib\\site-packages\\pydantic\\type_adapter.py\", line 277, in _init_core_attrs\n",
      "    self._core_schema = _get_schema(self._type, config_wrapper, parent_depth=self._parent_depth)\n",
      "  File \"c:\\anaconda3\\envs\\cv2\\lib\\site-packages\\pydantic\\type_adapter.py\", line 95, in _get_schema\n",
      "    schema = gen.generate_schema(type_)\n",
      "  File \"c:\\anaconda3\\envs\\cv2\\lib\\site-packages\\pydantic\\_internal\\_generate_schema.py\", line 655, in generate_schema\n",
      "    schema = self._generate_schema_inner(obj)\n",
      "  File \"c:\\anaconda3\\envs\\cv2\\lib\\site-packages\\pydantic\\_internal\\_generate_schema.py\", line 908, in _generate_schema_inner\n",
      "    return self._annotated_schema(obj)\n",
      "  File \"c:\\anaconda3\\envs\\cv2\\lib\\site-packages\\pydantic\\_internal\\_generate_schema.py\", line 2028, in _annotated_schema\n",
      "    schema = self._apply_annotations(source_type, annotations)\n",
      "  File \"c:\\anaconda3\\envs\\cv2\\lib\\site-packages\\pydantic\\_internal\\_generate_schema.py\", line 2107, in _apply_annotations\n",
      "    schema = get_inner_schema(source_type)\n",
      "  File \"c:\\anaconda3\\envs\\cv2\\lib\\site-packages\\pydantic\\_internal\\_schema_generation_shared.py\", line 83, in __call__\n",
      "    schema = self._handler(source_type)\n",
      "  File \"c:\\anaconda3\\envs\\cv2\\lib\\site-packages\\pydantic\\_internal\\_generate_schema.py\", line 2189, in new_handler\n",
      "    schema = metadata_get_schema(source, get_inner_schema)\n",
      "  File \"c:\\anaconda3\\envs\\cv2\\lib\\site-packages\\pydantic\\_internal\\_generate_schema.py\", line 2185, in <lambda>\n",
      "    lambda source, handler: handler(source)\n",
      "  File \"c:\\anaconda3\\envs\\cv2\\lib\\site-packages\\pydantic\\_internal\\_schema_generation_shared.py\", line 83, in __call__\n",
      "    schema = self._handler(source_type)\n",
      "  File \"c:\\anaconda3\\envs\\cv2\\lib\\site-packages\\pydantic\\_internal\\_generate_schema.py\", line 2088, in inner_handler\n",
      "    schema = self._generate_schema_inner(obj)\n",
      "  File \"c:\\anaconda3\\envs\\cv2\\lib\\site-packages\\pydantic\\_internal\\_generate_schema.py\", line 929, in _generate_schema_inner\n",
      "    return self.match_type(obj)\n",
      "  File \"c:\\anaconda3\\envs\\cv2\\lib\\site-packages\\pydantic\\_internal\\_generate_schema.py\", line 1029, in match_type\n",
      "    return self._match_generic_type(obj, origin)\n",
      "  File \"c:\\anaconda3\\envs\\cv2\\lib\\site-packages\\pydantic\\_internal\\_generate_schema.py\", line 1058, in _match_generic_type\n",
      "    return self._union_schema(obj)\n",
      "  File \"c:\\anaconda3\\envs\\cv2\\lib\\site-packages\\pydantic\\_internal\\_generate_schema.py\", line 1378, in _union_schema\n",
      "    choices.append(self.generate_schema(arg))\n",
      "  File \"c:\\anaconda3\\envs\\cv2\\lib\\site-packages\\pydantic\\_internal\\_generate_schema.py\", line 655, in generate_schema\n",
      "    schema = self._generate_schema_inner(obj)\n",
      "  File \"c:\\anaconda3\\envs\\cv2\\lib\\site-packages\\pydantic\\_internal\\_generate_schema.py\", line 929, in _generate_schema_inner\n",
      "    return self.match_type(obj)\n",
      "  File \"c:\\anaconda3\\envs\\cv2\\lib\\site-packages\\pydantic\\_internal\\_generate_schema.py\", line 1038, in match_type\n",
      "    return self._unknown_type_schema(obj)\n",
      "  File \"c:\\anaconda3\\envs\\cv2\\lib\\site-packages\\pydantic\\_internal\\_generate_schema.py\", line 558, in _unknown_type_schema\n",
      "    raise PydanticSchemaGenerationError(\n",
      "pydantic.errors.PydanticSchemaGenerationError: Unable to generate pydantic-core schema for <class 'starlette.requests.Request'>. Set `arbitrary_types_allowed=True` in the model_config to ignore this error or implement `__get_pydantic_core_schema__` on your type to fully support it.\n",
      "\n",
      "If you got this error by calling handler(<some type>) within `__get_pydantic_core_schema__` then you likely need to call `handler.generate_schema(<some type>)` since we do not call `__get_pydantic_core_schema__` on `<some type>` otherwise to avoid infinite recursion.\n",
      "\n",
      "For further information visit https://errors.pydantic.dev/2.9/u/schema-for-unknown-type\n",
      "ERROR:    Exception in ASGI application\n",
      "Traceback (most recent call last):\n",
      "  File \"c:\\anaconda3\\envs\\cv2\\lib\\site-packages\\pydantic\\type_adapter.py\", line 270, in _init_core_attrs\n",
      "    self._core_schema = _getattr_no_parents(self._type, '__pydantic_core_schema__')\n",
      "  File \"c:\\anaconda3\\envs\\cv2\\lib\\site-packages\\pydantic\\type_adapter.py\", line 112, in _getattr_no_parents\n",
      "    raise AttributeError(attribute)\n",
      "AttributeError: __pydantic_core_schema__\n",
      "\n",
      "During handling of the above exception, another exception occurred:\n",
      "\n",
      "Traceback (most recent call last):\n",
      "  File \"C:\\Users\\shjung\\AppData\\Roaming\\Python\\Python38\\site-packages\\uvicorn\\protocols\\http\\h11_impl.py\", line 406, in run_asgi\n",
      "    result = await app(  # type: ignore[func-returns-value]\n",
      "  File \"C:\\Users\\shjung\\AppData\\Roaming\\Python\\Python38\\site-packages\\uvicorn\\middleware\\proxy_headers.py\", line 70, in __call__\n",
      "    return await self.app(scope, receive, send)\n",
      "  File \"C:\\Users\\shjung\\AppData\\Roaming\\Python\\Python38\\site-packages\\fastapi\\applications.py\", line 1054, in __call__\n",
      "    await super().__call__(scope, receive, send)\n",
      "  File \"C:\\Users\\shjung\\AppData\\Roaming\\Python\\Python38\\site-packages\\starlette\\applications.py\", line 113, in __call__\n",
      "    await self.middleware_stack(scope, receive, send)\n",
      "  File \"C:\\Users\\shjung\\AppData\\Roaming\\Python\\Python38\\site-packages\\starlette\\middleware\\errors.py\", line 187, in __call__\n",
      "    raise exc\n",
      "  File \"C:\\Users\\shjung\\AppData\\Roaming\\Python\\Python38\\site-packages\\starlette\\middleware\\errors.py\", line 165, in __call__\n",
      "    await self.app(scope, receive, _send)\n",
      "  File \"C:\\Users\\shjung\\AppData\\Roaming\\Python\\Python38\\site-packages\\starlette\\middleware\\cors.py\", line 93, in __call__\n",
      "    await self.simple_response(scope, receive, send, request_headers=headers)\n",
      "  File \"C:\\Users\\shjung\\AppData\\Roaming\\Python\\Python38\\site-packages\\starlette\\middleware\\cors.py\", line 144, in simple_response\n",
      "    await self.app(scope, receive, send)\n",
      "  File \"C:\\Users\\shjung\\AppData\\Roaming\\Python\\Python38\\site-packages\\starlette\\middleware\\exceptions.py\", line 62, in __call__\n",
      "    await wrap_app_handling_exceptions(self.app, conn)(scope, receive, send)\n",
      "  File \"C:\\Users\\shjung\\AppData\\Roaming\\Python\\Python38\\site-packages\\starlette\\_exception_handler.py\", line 62, in wrapped_app\n",
      "    raise exc\n",
      "  File \"C:\\Users\\shjung\\AppData\\Roaming\\Python\\Python38\\site-packages\\starlette\\_exception_handler.py\", line 51, in wrapped_app\n",
      "    await app(scope, receive, sender)\n",
      "  File \"C:\\Users\\shjung\\AppData\\Roaming\\Python\\Python38\\site-packages\\starlette\\routing.py\", line 715, in __call__\n",
      "    await self.middleware_stack(scope, receive, send)\n",
      "  File \"C:\\Users\\shjung\\AppData\\Roaming\\Python\\Python38\\site-packages\\starlette\\routing.py\", line 735, in app\n",
      "    await route.handle(scope, receive, send)\n",
      "  File \"C:\\Users\\shjung\\AppData\\Roaming\\Python\\Python38\\site-packages\\starlette\\routing.py\", line 288, in handle\n",
      "    await self.app(scope, receive, send)\n",
      "  File \"C:\\Users\\shjung\\AppData\\Roaming\\Python\\Python38\\site-packages\\starlette\\routing.py\", line 76, in app\n",
      "    await wrap_app_handling_exceptions(app, request)(scope, receive, send)\n",
      "  File \"C:\\Users\\shjung\\AppData\\Roaming\\Python\\Python38\\site-packages\\starlette\\_exception_handler.py\", line 62, in wrapped_app\n",
      "    raise exc\n",
      "  File \"C:\\Users\\shjung\\AppData\\Roaming\\Python\\Python38\\site-packages\\starlette\\_exception_handler.py\", line 51, in wrapped_app\n",
      "    await app(scope, receive, sender)\n",
      "  File \"C:\\Users\\shjung\\AppData\\Roaming\\Python\\Python38\\site-packages\\starlette\\routing.py\", line 73, in app\n",
      "    response = await f(request)\n",
      "  File \"C:\\Users\\shjung\\AppData\\Roaming\\Python\\Python38\\site-packages\\fastapi\\routing.py\", line 291, in app\n",
      "    solved_result = await solve_dependencies(\n",
      "  File \"C:\\Users\\shjung\\AppData\\Roaming\\Python\\Python38\\site-packages\\fastapi\\dependencies\\utils.py\", line 656, in solve_dependencies\n",
      "    ) = await request_body_to_args(  # body_params checked above\n",
      "  File \"C:\\Users\\shjung\\AppData\\Roaming\\Python\\Python38\\site-packages\\fastapi\\dependencies\\utils.py\", line 881, in request_body_to_args\n",
      "    fields_to_extract = get_cached_model_fields(first_field.type_)\n",
      "  File \"C:\\Users\\shjung\\AppData\\Roaming\\Python\\Python38\\site-packages\\fastapi\\_compat.py\", line 657, in get_cached_model_fields\n",
      "    return get_model_fields(model)\n",
      "  File \"C:\\Users\\shjung\\AppData\\Roaming\\Python\\Python38\\site-packages\\fastapi\\_compat.py\", line 284, in get_model_fields\n",
      "    return [\n",
      "  File \"C:\\Users\\shjung\\AppData\\Roaming\\Python\\Python38\\site-packages\\fastapi\\_compat.py\", line 285, in <listcomp>\n",
      "    ModelField(field_info=field_info, name=name)\n",
      "  File \"<string>\", line 6, in __init__\n",
      "  File \"C:\\Users\\shjung\\AppData\\Roaming\\Python\\Python38\\site-packages\\fastapi\\_compat.py\", line 110, in __post_init__\n",
      "    self._type_adapter: TypeAdapter[Any] = TypeAdapter(\n",
      "  File \"c:\\anaconda3\\envs\\cv2\\lib\\site-packages\\pydantic\\type_adapter.py\", line 257, in __init__\n",
      "    self._init_core_attrs(rebuild_mocks=False)\n",
      "  File \"c:\\anaconda3\\envs\\cv2\\lib\\site-packages\\pydantic\\type_adapter.py\", line 135, in wrapped\n",
      "    return func(self, *args, **kwargs)\n",
      "  File \"c:\\anaconda3\\envs\\cv2\\lib\\site-packages\\pydantic\\type_adapter.py\", line 277, in _init_core_attrs\n",
      "    self._core_schema = _get_schema(self._type, config_wrapper, parent_depth=self._parent_depth)\n",
      "  File \"c:\\anaconda3\\envs\\cv2\\lib\\site-packages\\pydantic\\type_adapter.py\", line 95, in _get_schema\n",
      "    schema = gen.generate_schema(type_)\n",
      "  File \"c:\\anaconda3\\envs\\cv2\\lib\\site-packages\\pydantic\\_internal\\_generate_schema.py\", line 655, in generate_schema\n",
      "    schema = self._generate_schema_inner(obj)\n",
      "  File \"c:\\anaconda3\\envs\\cv2\\lib\\site-packages\\pydantic\\_internal\\_generate_schema.py\", line 908, in _generate_schema_inner\n",
      "    return self._annotated_schema(obj)\n",
      "  File \"c:\\anaconda3\\envs\\cv2\\lib\\site-packages\\pydantic\\_internal\\_generate_schema.py\", line 2028, in _annotated_schema\n",
      "    schema = self._apply_annotations(source_type, annotations)\n",
      "  File \"c:\\anaconda3\\envs\\cv2\\lib\\site-packages\\pydantic\\_internal\\_generate_schema.py\", line 2107, in _apply_annotations\n",
      "    schema = get_inner_schema(source_type)\n",
      "  File \"c:\\anaconda3\\envs\\cv2\\lib\\site-packages\\pydantic\\_internal\\_schema_generation_shared.py\", line 83, in __call__\n",
      "    schema = self._handler(source_type)\n",
      "  File \"c:\\anaconda3\\envs\\cv2\\lib\\site-packages\\pydantic\\_internal\\_generate_schema.py\", line 2189, in new_handler\n",
      "    schema = metadata_get_schema(source, get_inner_schema)\n",
      "  File \"c:\\anaconda3\\envs\\cv2\\lib\\site-packages\\pydantic\\_internal\\_generate_schema.py\", line 2185, in <lambda>\n",
      "    lambda source, handler: handler(source)\n",
      "  File \"c:\\anaconda3\\envs\\cv2\\lib\\site-packages\\pydantic\\_internal\\_schema_generation_shared.py\", line 83, in __call__\n",
      "    schema = self._handler(source_type)\n",
      "  File \"c:\\anaconda3\\envs\\cv2\\lib\\site-packages\\pydantic\\_internal\\_generate_schema.py\", line 2088, in inner_handler\n",
      "    schema = self._generate_schema_inner(obj)\n",
      "  File \"c:\\anaconda3\\envs\\cv2\\lib\\site-packages\\pydantic\\_internal\\_generate_schema.py\", line 929, in _generate_schema_inner\n",
      "    return self.match_type(obj)\n",
      "  File \"c:\\anaconda3\\envs\\cv2\\lib\\site-packages\\pydantic\\_internal\\_generate_schema.py\", line 1029, in match_type\n",
      "    return self._match_generic_type(obj, origin)\n",
      "  File \"c:\\anaconda3\\envs\\cv2\\lib\\site-packages\\pydantic\\_internal\\_generate_schema.py\", line 1058, in _match_generic_type\n",
      "    return self._union_schema(obj)\n",
      "  File \"c:\\anaconda3\\envs\\cv2\\lib\\site-packages\\pydantic\\_internal\\_generate_schema.py\", line 1378, in _union_schema\n",
      "    choices.append(self.generate_schema(arg))\n",
      "  File \"c:\\anaconda3\\envs\\cv2\\lib\\site-packages\\pydantic\\_internal\\_generate_schema.py\", line 655, in generate_schema\n",
      "    schema = self._generate_schema_inner(obj)\n",
      "  File \"c:\\anaconda3\\envs\\cv2\\lib\\site-packages\\pydantic\\_internal\\_generate_schema.py\", line 929, in _generate_schema_inner\n",
      "    return self.match_type(obj)\n",
      "  File \"c:\\anaconda3\\envs\\cv2\\lib\\site-packages\\pydantic\\_internal\\_generate_schema.py\", line 1038, in match_type\n",
      "    return self._unknown_type_schema(obj)\n",
      "  File \"c:\\anaconda3\\envs\\cv2\\lib\\site-packages\\pydantic\\_internal\\_generate_schema.py\", line 558, in _unknown_type_schema\n",
      "    raise PydanticSchemaGenerationError(\n",
      "pydantic.errors.PydanticSchemaGenerationError: Unable to generate pydantic-core schema for <class 'starlette.requests.Request'>. Set `arbitrary_types_allowed=True` in the model_config to ignore this error or implement `__get_pydantic_core_schema__` on your type to fully support it.\n",
      "\n",
      "If you got this error by calling handler(<some type>) within `__get_pydantic_core_schema__` then you likely need to call `handler.generate_schema(<some type>)` since we do not call `__get_pydantic_core_schema__` on `<some type>` otherwise to avoid infinite recursion.\n",
      "\n",
      "For further information visit https://errors.pydantic.dev/2.9/u/schema-for-unknown-type\n",
      "ERROR:    Exception in ASGI application\n",
      "Traceback (most recent call last):\n",
      "  File \"c:\\anaconda3\\envs\\cv2\\lib\\site-packages\\pydantic\\type_adapter.py\", line 270, in _init_core_attrs\n",
      "    self._core_schema = _getattr_no_parents(self._type, '__pydantic_core_schema__')\n",
      "  File \"c:\\anaconda3\\envs\\cv2\\lib\\site-packages\\pydantic\\type_adapter.py\", line 112, in _getattr_no_parents\n",
      "    raise AttributeError(attribute)\n",
      "AttributeError: __pydantic_core_schema__\n",
      "\n",
      "During handling of the above exception, another exception occurred:\n",
      "\n",
      "Traceback (most recent call last):\n",
      "  File \"C:\\Users\\shjung\\AppData\\Roaming\\Python\\Python38\\site-packages\\uvicorn\\protocols\\http\\h11_impl.py\", line 406, in run_asgi\n",
      "    result = await app(  # type: ignore[func-returns-value]\n",
      "  File \"C:\\Users\\shjung\\AppData\\Roaming\\Python\\Python38\\site-packages\\uvicorn\\middleware\\proxy_headers.py\", line 70, in __call__\n",
      "    return await self.app(scope, receive, send)\n",
      "  File \"C:\\Users\\shjung\\AppData\\Roaming\\Python\\Python38\\site-packages\\fastapi\\applications.py\", line 1054, in __call__\n",
      "    await super().__call__(scope, receive, send)\n",
      "  File \"C:\\Users\\shjung\\AppData\\Roaming\\Python\\Python38\\site-packages\\starlette\\applications.py\", line 113, in __call__\n",
      "    await self.middleware_stack(scope, receive, send)\n",
      "  File \"C:\\Users\\shjung\\AppData\\Roaming\\Python\\Python38\\site-packages\\starlette\\middleware\\errors.py\", line 187, in __call__\n",
      "    raise exc\n",
      "  File \"C:\\Users\\shjung\\AppData\\Roaming\\Python\\Python38\\site-packages\\starlette\\middleware\\errors.py\", line 165, in __call__\n",
      "    await self.app(scope, receive, _send)\n",
      "  File \"C:\\Users\\shjung\\AppData\\Roaming\\Python\\Python38\\site-packages\\starlette\\middleware\\cors.py\", line 93, in __call__\n",
      "    await self.simple_response(scope, receive, send, request_headers=headers)\n",
      "  File \"C:\\Users\\shjung\\AppData\\Roaming\\Python\\Python38\\site-packages\\starlette\\middleware\\cors.py\", line 144, in simple_response\n",
      "    await self.app(scope, receive, send)\n",
      "  File \"C:\\Users\\shjung\\AppData\\Roaming\\Python\\Python38\\site-packages\\starlette\\middleware\\exceptions.py\", line 62, in __call__\n",
      "    await wrap_app_handling_exceptions(self.app, conn)(scope, receive, send)\n",
      "  File \"C:\\Users\\shjung\\AppData\\Roaming\\Python\\Python38\\site-packages\\starlette\\_exception_handler.py\", line 62, in wrapped_app\n",
      "    raise exc\n",
      "  File \"C:\\Users\\shjung\\AppData\\Roaming\\Python\\Python38\\site-packages\\starlette\\_exception_handler.py\", line 51, in wrapped_app\n",
      "    await app(scope, receive, sender)\n",
      "  File \"C:\\Users\\shjung\\AppData\\Roaming\\Python\\Python38\\site-packages\\starlette\\routing.py\", line 715, in __call__\n",
      "    await self.middleware_stack(scope, receive, send)\n",
      "  File \"C:\\Users\\shjung\\AppData\\Roaming\\Python\\Python38\\site-packages\\starlette\\routing.py\", line 735, in app\n",
      "    await route.handle(scope, receive, send)\n",
      "  File \"C:\\Users\\shjung\\AppData\\Roaming\\Python\\Python38\\site-packages\\starlette\\routing.py\", line 288, in handle\n",
      "    await self.app(scope, receive, send)\n",
      "  File \"C:\\Users\\shjung\\AppData\\Roaming\\Python\\Python38\\site-packages\\starlette\\routing.py\", line 76, in app\n",
      "    await wrap_app_handling_exceptions(app, request)(scope, receive, send)\n",
      "  File \"C:\\Users\\shjung\\AppData\\Roaming\\Python\\Python38\\site-packages\\starlette\\_exception_handler.py\", line 62, in wrapped_app\n",
      "    raise exc\n",
      "  File \"C:\\Users\\shjung\\AppData\\Roaming\\Python\\Python38\\site-packages\\starlette\\_exception_handler.py\", line 51, in wrapped_app\n",
      "    await app(scope, receive, sender)\n",
      "  File \"C:\\Users\\shjung\\AppData\\Roaming\\Python\\Python38\\site-packages\\starlette\\routing.py\", line 73, in app\n",
      "    response = await f(request)\n",
      "  File \"C:\\Users\\shjung\\AppData\\Roaming\\Python\\Python38\\site-packages\\fastapi\\routing.py\", line 291, in app\n",
      "    solved_result = await solve_dependencies(\n",
      "  File \"C:\\Users\\shjung\\AppData\\Roaming\\Python\\Python38\\site-packages\\fastapi\\dependencies\\utils.py\", line 656, in solve_dependencies\n",
      "    ) = await request_body_to_args(  # body_params checked above\n",
      "  File \"C:\\Users\\shjung\\AppData\\Roaming\\Python\\Python38\\site-packages\\fastapi\\dependencies\\utils.py\", line 881, in request_body_to_args\n",
      "    fields_to_extract = get_cached_model_fields(first_field.type_)\n",
      "  File \"C:\\Users\\shjung\\AppData\\Roaming\\Python\\Python38\\site-packages\\fastapi\\_compat.py\", line 657, in get_cached_model_fields\n",
      "    return get_model_fields(model)\n",
      "  File \"C:\\Users\\shjung\\AppData\\Roaming\\Python\\Python38\\site-packages\\fastapi\\_compat.py\", line 284, in get_model_fields\n",
      "    return [\n",
      "  File \"C:\\Users\\shjung\\AppData\\Roaming\\Python\\Python38\\site-packages\\fastapi\\_compat.py\", line 285, in <listcomp>\n",
      "    ModelField(field_info=field_info, name=name)\n",
      "  File \"<string>\", line 6, in __init__\n",
      "  File \"C:\\Users\\shjung\\AppData\\Roaming\\Python\\Python38\\site-packages\\fastapi\\_compat.py\", line 110, in __post_init__\n",
      "    self._type_adapter: TypeAdapter[Any] = TypeAdapter(\n",
      "  File \"c:\\anaconda3\\envs\\cv2\\lib\\site-packages\\pydantic\\type_adapter.py\", line 257, in __init__\n",
      "    self._init_core_attrs(rebuild_mocks=False)\n",
      "  File \"c:\\anaconda3\\envs\\cv2\\lib\\site-packages\\pydantic\\type_adapter.py\", line 135, in wrapped\n",
      "    return func(self, *args, **kwargs)\n",
      "  File \"c:\\anaconda3\\envs\\cv2\\lib\\site-packages\\pydantic\\type_adapter.py\", line 277, in _init_core_attrs\n",
      "    self._core_schema = _get_schema(self._type, config_wrapper, parent_depth=self._parent_depth)\n",
      "  File \"c:\\anaconda3\\envs\\cv2\\lib\\site-packages\\pydantic\\type_adapter.py\", line 95, in _get_schema\n",
      "    schema = gen.generate_schema(type_)\n",
      "  File \"c:\\anaconda3\\envs\\cv2\\lib\\site-packages\\pydantic\\_internal\\_generate_schema.py\", line 655, in generate_schema\n",
      "    schema = self._generate_schema_inner(obj)\n",
      "  File \"c:\\anaconda3\\envs\\cv2\\lib\\site-packages\\pydantic\\_internal\\_generate_schema.py\", line 908, in _generate_schema_inner\n",
      "    return self._annotated_schema(obj)\n",
      "  File \"c:\\anaconda3\\envs\\cv2\\lib\\site-packages\\pydantic\\_internal\\_generate_schema.py\", line 2028, in _annotated_schema\n",
      "    schema = self._apply_annotations(source_type, annotations)\n",
      "  File \"c:\\anaconda3\\envs\\cv2\\lib\\site-packages\\pydantic\\_internal\\_generate_schema.py\", line 2107, in _apply_annotations\n",
      "    schema = get_inner_schema(source_type)\n",
      "  File \"c:\\anaconda3\\envs\\cv2\\lib\\site-packages\\pydantic\\_internal\\_schema_generation_shared.py\", line 83, in __call__\n",
      "    schema = self._handler(source_type)\n",
      "  File \"c:\\anaconda3\\envs\\cv2\\lib\\site-packages\\pydantic\\_internal\\_generate_schema.py\", line 2189, in new_handler\n",
      "    schema = metadata_get_schema(source, get_inner_schema)\n",
      "  File \"c:\\anaconda3\\envs\\cv2\\lib\\site-packages\\pydantic\\_internal\\_generate_schema.py\", line 2185, in <lambda>\n",
      "    lambda source, handler: handler(source)\n",
      "  File \"c:\\anaconda3\\envs\\cv2\\lib\\site-packages\\pydantic\\_internal\\_schema_generation_shared.py\", line 83, in __call__\n",
      "    schema = self._handler(source_type)\n",
      "  File \"c:\\anaconda3\\envs\\cv2\\lib\\site-packages\\pydantic\\_internal\\_generate_schema.py\", line 2088, in inner_handler\n",
      "    schema = self._generate_schema_inner(obj)\n",
      "  File \"c:\\anaconda3\\envs\\cv2\\lib\\site-packages\\pydantic\\_internal\\_generate_schema.py\", line 929, in _generate_schema_inner\n",
      "    return self.match_type(obj)\n",
      "  File \"c:\\anaconda3\\envs\\cv2\\lib\\site-packages\\pydantic\\_internal\\_generate_schema.py\", line 1029, in match_type\n",
      "    return self._match_generic_type(obj, origin)\n",
      "  File \"c:\\anaconda3\\envs\\cv2\\lib\\site-packages\\pydantic\\_internal\\_generate_schema.py\", line 1058, in _match_generic_type\n",
      "    return self._union_schema(obj)\n",
      "  File \"c:\\anaconda3\\envs\\cv2\\lib\\site-packages\\pydantic\\_internal\\_generate_schema.py\", line 1378, in _union_schema\n",
      "    choices.append(self.generate_schema(arg))\n",
      "  File \"c:\\anaconda3\\envs\\cv2\\lib\\site-packages\\pydantic\\_internal\\_generate_schema.py\", line 655, in generate_schema\n",
      "    schema = self._generate_schema_inner(obj)\n",
      "  File \"c:\\anaconda3\\envs\\cv2\\lib\\site-packages\\pydantic\\_internal\\_generate_schema.py\", line 929, in _generate_schema_inner\n",
      "    return self.match_type(obj)\n",
      "  File \"c:\\anaconda3\\envs\\cv2\\lib\\site-packages\\pydantic\\_internal\\_generate_schema.py\", line 1038, in match_type\n",
      "    return self._unknown_type_schema(obj)\n",
      "  File \"c:\\anaconda3\\envs\\cv2\\lib\\site-packages\\pydantic\\_internal\\_generate_schema.py\", line 558, in _unknown_type_schema\n",
      "    raise PydanticSchemaGenerationError(\n",
      "pydantic.errors.PydanticSchemaGenerationError: Unable to generate pydantic-core schema for <class 'starlette.requests.Request'>. Set `arbitrary_types_allowed=True` in the model_config to ignore this error or implement `__get_pydantic_core_schema__` on your type to fully support it.\n",
      "\n",
      "If you got this error by calling handler(<some type>) within `__get_pydantic_core_schema__` then you likely need to call `handler.generate_schema(<some type>)` since we do not call `__get_pydantic_core_schema__` on `<some type>` otherwise to avoid infinite recursion.\n",
      "\n",
      "For further information visit https://errors.pydantic.dev/2.9/u/schema-for-unknown-type\n"
     ]
    }
   ],
   "source": [
    "\n",
    "import random\n",
    "import gradio as gr\n",
    "\n",
    "\n",
    "def random_response(message, history):\n",
    "    products = {\n",
    "        \"적금 상품\" : \"111111111111\",\n",
    "        \"대출 상품\" : \"222222222222\",\n",
    "        \"신용 카드\" : \"33333333333\",\n",
    "        \"예금 상품\" : \"444444444444\",\n",
    "        \"주택청약 통장\" : \"5555555555555\"\n",
    "    }\n",
    "    greetings = [\n",
    "        \"고객님 안녕하세요.\",\n",
    "        \"고객님 어떤 은행 상품을 안내해드릴까요?\"\n",
    "    ]\n",
    "\n",
    "    for idx in products.keys():        \n",
    "        if idx == message:\n",
    "            response = products[message]      \n",
    "            break      \n",
    "        else:\n",
    "            response = random.choice(greetings)\n",
    "\n",
    "    yield response\n",
    "\n",
    "\n",
    "demo = gr.ChatInterface(random_response)\n",
    "\n",
    "if __name__ == \"__main__\":\n",
    "    demo.launch(share=True)"
   ]
  },
  {
   "cell_type": "code",
   "execution_count": null,
   "metadata": {},
   "outputs": [],
   "source": [
    "import random\n",
    "import gradio as gr\n",
    "\n",
    "\n",
    "def random_response(message, history):\n",
    "    products = {\n",
    "        \"적금 상품\": \"111111111111\",\n",
    "        \"대출 상품\": \"222222222222\",\n",
    "        \"신용 카드\": \"33333333333\",\n",
    "        \"예금 상품\": \"444444444444\",\n",
    "        \"주택청약 통장\": \"5555555555555\"\n",
    "    }\n",
    "    greetings = [\n",
    "        \"고객님 안녕하세요.\",\n",
    "        \"고객님 어떤 은행 상품을 안내해드릴까요?\"\n",
    "    ]\n",
    "\n",
    "    # 상품이 있는지 확인하고 있으면 반환, 없으면 인사말 반환\n",
    "    if message in products:\n",
    "        response = products[message]\n",
    "    else:\n",
    "        response = random.choice(greetings)\n",
    "\n",
    "    return response  # yield 대신 return 사용\n",
    "\n",
    "\n",
    "demo = gr.ChatInterface(random_response)\n",
    "\n",
    "if __name__ == \"__main__\":\n",
    "    demo.launch(share=True)\n"
   ]
  }
 ],
 "metadata": {
  "kernelspec": {
   "display_name": "cv2",
   "language": "python",
   "name": "python3"
  },
  "language_info": {
   "codemirror_mode": {
    "name": "ipython",
    "version": 3
   },
   "file_extension": ".py",
   "mimetype": "text/x-python",
   "name": "python",
   "nbconvert_exporter": "python",
   "pygments_lexer": "ipython3",
   "version": "3.8.19"
  }
 },
 "nbformat": 4,
 "nbformat_minor": 2
}
